Workbook

Sheet Master Submitted DPDs
A1: HZ Ref | B1: LDF No | C1: Region | D1: LPA | E1: Title | F1: DPD Type | G1: Grade | H1: Actual Publication Date_Reg 19 | I1: Actual Publication Notes | J1: Actual Submission Date_Reg 22 | K1: Actual Submission Notes | L1: FIVE YEAR SUPPLY OF LAND | M1: Date of Appointment | N1: Date of Appointment Notes | O1: Actual Hearing Start Date | P1: Actual Hearing Start Notes | Q1: Hearings Close Date | R1: Hearings Close Notes | S1: Advisory Visit Prep | T1: Advisory Visit Meeting | U1: Advisory Visit Travel | V1: Advisory Visit Reporting | W1: Local Plan Admin | X1: Prep days* | Y1: Hearing days* | Z1: Post Hearing Letter(s) | AA1: SV days* | AB1: Travel days | AC1: Local Plan MM Prep | AD1: Reptg days* | AE1: Total Days | AF1: Days LDF Ref | AG1: Date Given To LPA For Receipt of Fact Check | AH1: Date Given To LPA For Receipt of Fact Check Notes | AI1: Draft Report Sent to QA Group Date | AJ1: Draft Report Sent to QA Group Notes | AK1: Fact Check Report Received From INSP Date | AL1: Fact Check Report Received From INSP Notes | AM1: Fact Check Report Dispatch Date | AN1: Fact Check Report Dispatch Notes | AO1: Final Report Issued Date | AP1: Final Report Issued Notes | AQ1: Adoption Date | AR1: Adoption Notes | AS1: Withdrawn Date | AT1: Withdrawn Notes | AU1: Status | AV1: Total Weeks | AW1: Hearing Close to_ final _report | AX1: NOTES | AY1: LPA Lookup | AZ1: Submission Date | BA1: Reports Issued
A2: NA | B2: 1570 | C2: WM | D2: Warwick | E2: Local Plan | F2: LP | G2: B | H2: 41775 | J2: 42034 | M2: 42034 | O2: 42130 | Q2: 42719 | X2: 57.52 | Y2: 29.32 | AA2: 3.69 | AB2: 14.15 | AD2: 75 | AE2: =AllPlans[[#This Row],[Prep days*]]+AllPlans[[#This Row],[Hearing days*]]+AllPlans[[#This Row],[SV days*]]+AllPlans[[#This Row],[Travel days]]+AllPlans[[#This Row],[Reptg days*]] -> 179.68 | AG2: 42937 | AI2: 42923 | AK2: 42933 | AM2: 42934 | AO2: 42944 | AQ2: 42999 | AU2: SOU | AV2: 130 | AW2: =SUM(AO2-Q2)/7 -> 32.142857 | AY2: E07000222 | AZ2: =TEXT(J2,"MMM YY") -> Jan 15 | BA2: =TEXT(AO2,"MMM YY") -> Jul 17
A3: NA | B3: 1089 | C3: SE | D3: Arun | E3: Local Plan | F3: LP | G3: A | H3: 41942 | J3: 42034 | M3: 42034 | O3: 42157 | Q3: 43006 | X3: 73.76 | Y3: 12.36 | AB3: 5.37 | AD3: 37.79 | AE3: =AllPlans[[#This Row],[Prep days*]]+AllPlans[[#This Row],[Hearing days*]]+AllPlans[[#This Row],[SV days*]]+AllPlans[[#This Row],[Travel days]]+AllPlans[[#This Row],[Reptg days*]] -> 129.28 | AG3: 43259 | AI3: 43217 | AK3: 43251 | AM3: 43251 | AO3: 43285 | AQ3: 43299 | AU3: SOU | AV3: =SUM(AO3-J3)/7 -> 178.71429 | AW3: =SUM(AO3-Q3)/7 -> 39.857143 | AY3: E07000224 | AZ3: =TEXT(J3,"MMM YY") -> Jan 15 | BA3: =TEXT(AO3,"MMM YY") -> Jul 18
A4: NA | B4: 1617 | C4: WM | D4: Tamworth | E4: Local Plan | F4: LP | G4: A | H4: 41934 | J4: 42040 | M4: 42041 | O4: 42171 | Q4: 42180 | X4: 58.17 | Y4: 9.08 | AB4: 4.39 | AD4: 34.27 | AE4: =AllPlans[[#This Row],[Prep days*]]+AllPlans[[#This Row],[Hearing days*]]+AllPlans[[#This Row],[SV days*]]+AllPlans[[#This Row],[Travel days]]+AllPlans[[#This Row],[Reptg days*]] -> 105.91 | AG4: 42396 | AI4: 42367 | AK4: 42396 | AM4: 42396 | AO4: 42403 | AQ4: 42423 | AU4: SOU | AV4: 85.142857 | AW4: =SUM(AO4-Q4)/7 -> 31.857143 | AY4: E07000199 | AZ4: =TEXT(J4,"MMM YY") -> Feb 15 | BA4: =TEXT(AO4,"MMM YY") -> Feb 16
A5: NA | B5: 1435 | C5: SW | D5: Cornwall | E5: Local Plan Strategic Policies | F5: LP | G5: B | H5: 41715 | J5: 42040 | M5: 42041 | O5: 42142 | Q5: 42514 | X5: 23.06 | Y5: 4.39 | AA5: 0.2 | AB5: 4.07 | AD5: 32.63 | AE5: =AllPlans[[#This Row],[Prep days*]]+AllPlans[[#This Row],[Hearing days*]]+AllPlans[[#This Row],[SV days*]]+AllPlans[[#This Row],[Travel days]]+AllPlans[[#This Row],[Reptg days*]] -> 64.35 | AG5: 42622 | AI5: 42576 | AK5: 42618 | AM5: 42618 | AO5: 42636 | AQ5: 42696 | AU5: SOU | AV5: 51.857143 | AW5: =SUM(AO5-Q5)/7 -> 17.428571 | AY5: E06000052 | AZ5: =TEXT(J5,"MMM YY") -> Feb 15 | BA5: =TEXT(AO5,"MMM YY") -> Sep 16
A6: NA | B6: 1609 | C6: E | D6: Broadland | E6: Growth Triangle AAP | F6: AAP | G6: D | H6: 41855 | J6: 42046 | M6: 42047 | O6: 42206 | Q6: 42209 | X6: 16.33 | Y6: 3.58 | AB6: 1.22 | AD6: 18.76 | AE6: =AllPlans[[#This Row],[Prep days*]]+AllPlans[[#This Row],[Hearing days*]]+AllPlans[[#This Row],[SV days*]]+AllPlans[[#This Row],[Travel days]]+AllPlans[[#This Row],[Reptg days*]] -> 39.89 | AG6: 42502 | AI6: 42473 | AK6: 42488 | AM6: 42493 | AO6: 42507 | AQ6: 42555 | AU6: SOU | AV6: 65.857143 | AW6: =SUM(AO6-Q6)/7 -> 42.571429 | AY6: E07000144 | AZ6: =TEXT(J6,"MMM YY") -> Feb 15 | BA6: =TEXT(AO6,"MMM YY") -> May 16
A7: NA | B7: 1530 | C7: YH | D7: Leeds | E7: Natural Resources & Waste LP Policies Minerals 13 & 14 | F7: M&W | G7: C | H7: 41960 | J7: 42052 | M7: 42052 | O7: 42151 | Q7: 42152 | X7: 12 | Y7: 1.5 | AB7: 1 | AD7: 6 | AE7: =AllPlans[[#This Row],[Prep days*]]+AllPlans[[#This Row],[Hearing days*]]+AllPlans[[#This Row],[SV days*]]+AllPlans[[#This Row],[Travel days]]+AllPlans[[#This Row],[Reptg days*]] -> 20.5 | AG7: 42244 | AI7: 42227 | AK7: 42234 | AM7: 42234 | AO7: 42244 | AQ7: 42263 | AU7: SOU | AV7: 27.428571 | AW7: =SUM(AO7-Q7)/7 -> 13.142857 | AY7: E08000035 | AZ7: =TEXT(J7,"MMM YY") -> Feb 15 | BA7: =TEXT(AO7,"MMM YY") -> Aug 15
A8: NA | B8: 1511 | C8: NW | D8: Preston | E8: Preston City Centre AAP | F8: AAP | G8: D | H8: 41936 | J8: 42062 | M8: 42062 | O8: 42332 | Q8: 42333 | X8: 17.45 | Y8: 2.17 | AA8: 0.41 | AB8: 1.48 | AD8: 13.49 | AE8: =AllPlans[[#This Row],[Prep days*]]+AllPlans[[#This Row],[Hearing days*]]+AllPlans[[#This Row],[SV days*]]+AllPlans[[#This Row],[Travel days]]+AllPlans[[#This Row],[Reptg days*]] -> 35 | AG8: 42531 | AI8: 42515 | AK8: 42529 | AM8: 42529 | AO8: 42542 | AQ8: 42551 | AU8: SOU | AV8: 68.571429 | AW8: =SUM(AO8-Q8)/7 -> 29.857143 | AY8: E07000123 | AZ8: =TEXT(J8,"MMM YY") -> Feb 15 | BA8: =TEXT(AO8,"MMM YY") -> Jun 16
A9: NA | B9: 1641 | C9: E | D9: South Norfolk | E9: Long Stratton AAP | F9: AAP | G9: D | H9: 41880 | J9: 42068 | O9: 42199 | Q9: 42201 | X9: 22.28 | Y9: 2.17 | AB9: 2.03 | AD9: 33.98 | AE9: =AllPlans[[#This Row],[Prep days*]]+AllPlans[[#This Row],[Hearing days*]]+AllPlans[[#This Row],[SV days*]]+AllPlans[[#This Row],[Travel days]]+AllPlans[[#This Row],[Reptg days*]] -> 60.46 | AG9: 42475 | AI9: 42433 | AK9: 42473 | AM9: 42474 | AO9: 42486 | AQ9: 42516 | AU9: SOU | AV9: 59.714286 | AW9: =SUM(AO9-Q9)/7 -> 40.714286 | AY9: E07000149 | AZ9: =TEXT(J9,"MMM YY") -> Mar 15 | BA9: =TEXT(AO9,"MMM YY") -> Apr 16
A10: NA | B10: 1625 | C10: Lon | D10: Wandsworth | E10: Local Plan Review | F10: LP | G10: A | H10: 41929 | J10: 42074 | M10: 42075 | O10: 42193 | Q10: 42200 | X10: 18.75 | Y10: 2.57 | AB10: 1.32 | AD10: 13.36 | AE10: =AllPlans[[#This Row],[Prep days*]]+AllPlans[[#This Row],[Hearing days*]]+AllPlans[[#This Row],[SV days*]]+AllPlans[[#This Row],[Travel days]]+AllPlans[[#This Row],[Reptg days*]] -> 36 | AG10: 42360 | AI10: 42338 | AK10: 42353 | AM10: 42353 | AO10: 42361 | AQ10: 42438 | AU10: SOU | AV10: 41 | AW10: =SUM(AO10-Q10)/7 -> 23 | AY10: E09000032 | AZ10: =TEXT(J10,"MMM YY") -> Mar 15 | BA10: =TEXT(AO10,"MMM YY") -> Dec 15
A11: NA | B11: 832 | C11: SE | D11: Vale of White Horse | E11: Local Plan part 1 | F11: LP | G11: A | H11: 41950 | J11: 42081 | M11: 42081 | O11: 42269 | Q11: 42418 | X11: 41.26 | Y11: 14.66 | AA11: 2.8 | AB11: 9.87 | AD11: 44.74 | AE11: =AllPlans[[#This Row],[Prep days*]]+AllPlans[[#This Row],[Hearing days*]]+AllPlans[[#This Row],[SV days*]]+AllPlans[[#This Row],[Travel days]]+AllPlans[[#This Row],[Reptg days*]] -> 113.33 | AG11: 42699 | AI11: 42688 | AK11: 42695 | AM11: 42695 | AO11: 42704 | AQ11: 42718 | AU11: SOU | AV11: 89 | AW11: =SUM(AO11-Q11)/7 -> 40.857143 | AY11: E07000180 | AZ11: =TEXT(J11,"MMM YY") -> Mar 15 | BA11: =TEXT(AO11,"MMM YY") -> Nov 16
A12: NA | B12: 1620 | C12: YH | D12: North Lincolnshire | E12: Lincolnshire Lakes AAP | F12: AAP | G12: D | H12: 41946 | J12: 42083 | M12: 42083 | O12: 42290 | Q12: 42297 | X12: 18.49 | Y12: 2.73 | AA12: 0.27 | AB12: 1.08 | AD12: 17.69 | AE12: =AllPlans[[#This Row],[Prep days*]]+AllPlans[[#This Row],[Hearing days*]]+AllPlans[[#This Row],[SV days*]]+AllPlans[[#This Row],[Travel days]]+AllPlans[[#This Row],[Reptg days*]] -> 40.26 | AG12: 42476 | AI12: 42450 | AK12: 42473 | AM12: 42472 | AO12: 42480 | AQ12: 42500 | AU12: SOU | AV12: 56.714286 | AW12: =SUM(AO12-Q12)/7 -> 26.142857 | AY12: E06000013 | AZ12: =TEXT(J12,"MMM YY") -> Mar 15 | BA12: =TEXT(AO12,"MMM YY") -> Apr 16
A13: NA | B13: 1630 | C13: SE | D13: Wealden | E13: Affordable Housing Delivery | F13: Other | G13: D | H13: 41974 | J13: 42088 | M13: 42088 | O13: 42144 | Q13: 42380 | X13: 12.53 | Y13: 2 | AB13: 2.71 | AD13: 15.52 | AE13: =AllPlans[[#This Row],[Prep days*]]+AllPlans[[#This Row],[Hearing days*]]+AllPlans[[#This Row],[SV days*]]+AllPlans[[#This Row],[Travel days]]+AllPlans[[#This Row],[Reptg days*]] -> 32.76 | AG13: 42419 | AI13: 42428 | AK13: 42418 | AM13: 42419 | AO13: 42424 | AQ13: 42508 | AU13: SOU | AV13: 48 | AW13: =SUM(AO13-Q13)/7 -> 6.2857143 | AY13: E07000065 | AZ13: =TEXT(J13,"MMM YY") -> Mar 15 | BA13: =TEXT(AO13,"MMM YY") -> Feb 16
A14: NA | B14: 1013 | C14: EM | D14: Hinckley and Bosworth | E14: Site Allocations & DM Policies | F14: SA | G14: B | H14: 41322 | J14: 42090 | M14: 42090 | O14: 42276 | Q14: 42284 | X14: 16 | Y14: 4 | AA14: 1.5 | AB14: 2.5 | AD14: 15 | AE14: =AllPlans[[#This Row],[Prep days*]]+AllPlans[[#This Row],[Hearing days*]]+AllPlans[[#This Row],[SV days*]]+AllPlans[[#This Row],[Travel days]]+AllPlans[[#This Row],[Reptg days*]] -> 39 | AG14: 42503 | AI14: 42485 | AK14: 42500 | AM14: 42501 | AO14: 42507 | AQ14: 42563 | AU14: SOU | AV14: 59.571429 | AW14: =SUM(AO14-Q14)/7 -> 31.857143 | AY14: E07000132 | AZ14: =TEXT(J14,"MMM YY") -> Mar 15 | BA14: =TEXT(AO14,"MMM YY") -> May 16
A15: NA | B15: 1636 | C15: SE | D15: Swale | E15: Local Plan part 1 | F15: LP | G15: A | H15: 41992 | J15: 42114 | M15: 42114 | O15: 42309 | Q15: 42774 | X15: 62.64 | Y15: 13.55 | AB15: 4.52 | AD15: 38.32 | AE15: =AllPlans[[#This Row],[Prep days*]]+AllPlans[[#This Row],[Hearing days*]]+AllPlans[[#This Row],[SV days*]]+AllPlans[[#This Row],[Travel days]]+AllPlans[[#This Row],[Reptg days*]] -> 119.03 | AG15: 42853 | AI15: 42829 | AK15: 42851 | AM15: 42852 | AO15: 42906 | AQ15: 42942 | AU15: SOU | AV15: 113.14286 | AW15: =SUM(AO15-Q15)/7 -> 18.857143 | AY15: E07000113 | AZ15: =TEXT(J15,"MMM YY") -> Apr 15 | BA15: =TEXT(AO15,"MMM YY") -> Jun 17
A16: NA | B16: 1637 | C16: E | D16: King's Lynn and West Norfolk | E16: Site Allocations & DM Policies | F16: SA | G16: B | H16: 42016 | J16: 42116 | M16: 42116 | O16: 42192 | Q16: 42327 | X16: 34.61 | Y16: 9.56 | AA16: 1.79 | AB16: 6.68 | AD16: 28.85 | AE16: =AllPlans[[#This Row],[Prep days*]]+AllPlans[[#This Row],[Hearing days*]]+AllPlans[[#This Row],[SV days*]]+AllPlans[[#This Row],[Travel days]]+AllPlans[[#This Row],[Reptg days*]] -> 81.49 | AG16: 42612 | AI16: 42577 | AK16: 42598 | AM16: 42599 | AO16: 42604 | AQ16: 42642 | AU16: SOU | AV16: 69.714286 | AW16: =SUM(AO16-Q16)/7 -> 39.571429 | AY16: E07000146 | AZ16: =TEXT(J16,"MMM YY") -> Apr 15 | BA16: =TEXT(AO16,"MMM YY") -> Aug 16
A17: NA | B17: 1639 | C17: EM | D17: Lincolnshire CC | E17: Core Strategy & DM Policies | F17: M&W | G17: 3 | H17: 42009 | J17: 42160 | M17: 42160 | O17: 42290 | Q17: 42293 | X17: 20.5 | Y17: 3.5 | AB17: 1 | AD17: 10 | AE17: =AllPlans[[#This Row],[Prep days*]]+AllPlans[[#This Row],[Hearing days*]]+AllPlans[[#This Row],[SV days*]]+AllPlans[[#This Row],[Travel days]]+AllPlans[[#This Row],[Reptg days*]] -> 35 | AG17: 42408 | AI17: 42395 | AK17: 42398 | AM17: 42398 | AO17: 42422 | AQ17: 42500 | AU17: SOU | AV17: 37.428571 | AW17: =SUM(AO17-Q17)/7 -> 18.428571 | AY17: E10000019 | AZ17: =TEXT(J17,"MMM YY") -> Jun 15 | BA17: =TEXT(AO17,"MMM YY") -> Feb 16
A18: NA | B18: 1042 | C18: SE | D18: Tunbridge Wells | E18: Site Allocations | F18: SA | G18: 3 | H18: 42044 | J18: 42163 | M18: 42163 | O18: 42318 | Q18: 42347 | X18: 30.5 | Y18: 7.24 | AA18: 2.13 | AB18: 4.36 | AD18: 15.16 | AE18: =AllPlans[[#This Row],[Prep days*]]+AllPlans[[#This Row],[Hearing days*]]+AllPlans[[#This Row],[SV days*]]+AllPlans[[#This Row],[Travel days]]+AllPlans[[#This Row],[Reptg days*]] -> 59.39 | AG18: 42521 | AI18: 42501 | AK18: 42517 | AM18: 42517 | AO18: 42530 | AQ18: 42571 | AU18: SOU | AV18: 52.428571 | AW18: =SUM(AO18-Q18)/7 -> 26.142857 | AY18: E07000116 | AZ18: =TEXT(J18,"MMM YY") -> Jun 15 | BA18: =TEXT(AO18,"MMM YY") -> Jun 16
A19: NA | B19: 1657 | C19: NW | D19: Carlisle | E19: Local Plan 2015-2030 | F19: LP | G19: 3 | H19: 42067 | J19: 42174 | M19: 42177 | O19: 42339 | Q19: 42389 | X19: 20.02 | Y19: 3.64 | AB19: 1.88 | AD19: 33.38 | AE19: =AllPlans[[#This Row],[Prep days*]]+AllPlans[[#This Row],[Hearing days*]]+AllPlans[[#This Row],[SV days*]]+AllPlans[[#This Row],[Travel days]]+AllPlans[[#This Row],[Reptg days*]] -> 58.92 | AG19: 42550 | AI19: 42528 | AK19: 42544 | AM19: 42544 | AO19: 42576 | AQ19: 42682 | AU19: SOU | AV19: 57.428571 | AW19: =SUM(AO19-Q19)/7 -> 26.714286 | AY19: E07000028 | AZ19: =TEXT(J19,"MMM YY") -> Jun 15 | BA19: =TEXT(AO19,"MMM YY") -> Jul 16
A20: NA | B20: 1668 | C20: SE | D20: East Hampshire | E20: Housing & Employment Allocations | F20: SA | G20: 3 | H20: 42104 | J20: 42194 | M20: 42195 | O20: 42304 | Q20: 42307 | X20: 16.7 | Y20: 3.78 | AB20: 0.94 | AD20: 12.16 | AE20: =AllPlans[[#This Row],[Prep days*]]+AllPlans[[#This Row],[Hearing days*]]+AllPlans[[#This Row],[SV days*]]+AllPlans[[#This Row],[Travel days]]+AllPlans[[#This Row],[Reptg days*]] -> 33.58 | AG20: 42419 | AI20: 42398 | AK20: 42409 | AM20: 42410 | AO20: 42415 | AQ20: 42467 | AU20: SOU | AV20: 33.857143 | AW20: =SUM(AO20-Q20)/7 -> 15.428571 | AY20: E07000085 | AZ20: =TEXT(J20,"MMM YY") -> Jul 15 | BA20: =TEXT(AO20,"MMM YY") -> Feb 16
A21: NA | B21: 1518 | C21: Lon | D21: Ealing | E21: Planning for Schools | F21: Other | G21: 2 | H21: 41690 | J21: 42194 | M21: 42194 | O21: 42319 | Q21: 42321 | X21: 20.08 | Y21: 3 | AA21: 2.43 | AB21: 2.56 | AD21: 19.61 | AE21: =AllPlans[[#This Row],[Prep days*]]+AllPlans[[#This Row],[Hearing days*]]+AllPlans[[#This Row],[SV days*]]+AllPlans[[#This Row],[Travel days]]+AllPlans[[#This Row],[Reptg days*]] -> 47.68 | AG21: 42426 | AI21: 42409 | AK21: 42423 | AM21: 42423 | AO21: 42431 | AQ21: 42500 | AU21: SOU | AV21: 31.571429 | AW21: =SUM(AO21-Q21)/7 -> 15.714286 | AY21: E09000009 | AZ21: =TEXT(J21,"MMM YY") -> Jul 15 | BA21: =TEXT(AO21,"MMM YY") -> Mar 16
A22: NA | B22: 1640 | C22: SW | D22: Taunton Deane | E22: Site Allocations & DMP | G22: 3 | H22: 42019 | J22: 42198 | M22: 42198 | O22: 42339 | Q22: 42465 | X22: 19.86 | Y22: 4.42 | AA22: 1.14 | AB22: 1.53 | AD22: 16.28 | AE22: =AllPlans[[#This Row],[Prep days*]]+AllPlans[[#This Row],[Hearing days*]]+AllPlans[[#This Row],[SV days*]]+AllPlans[[#This Row],[Travel days]]+AllPlans[[#This Row],[Reptg days*]] -> 43.23 | AG22: 42674 | AI22: 42654 | AK22: 42667 | AM22: 42667 | AO22: 42691 | AQ22: 42717 | AU22: SOU | AV22: 70.428571 | AW22: =SUM(AO22-Q22)/7 -> 32.285714 | AY22: E07000190 | AZ22: =TEXT(J22,"MMM YY") -> Jul 15 | BA22: =TEXT(AO22,"MMM YY") -> Nov 16
A23: NA | B23: 928 | C23: SE | D23: West Oxfordshire | E23: Local Plan | F23: LP | G23: 3 | H23: 42090 | J23: 42199 | M23: 42199 | O23: 42283 | Q23: 42936 | X23: 58.77 | Y23: 14.56 | AA23: 5.31 | AB23: 9.07 | AD23: 62.93 | AE23: =AllPlans[[#This Row],[Prep days*]]+AllPlans[[#This Row],[Hearing days*]]+AllPlans[[#This Row],[SV days*]]+AllPlans[[#This Row],[Travel days]]+AllPlans[[#This Row],[Reptg days*]] -> 150.64 | AG23: 43334 | AI23: 43307 | AK23: 43332 | AM23: 43332 | AO23: 43336 | AQ23: 43370 | AU23: SOU | AV23: =SUM(AO23-J23)/7 -> 162.42857 | AW23: =SUM(AO23-Q23)/7 -> 57.142857 | AY23: E07000181 | AZ23: =TEXT(J23,"MMM YY") -> Jul 15 | BA23: =TEXT(AO23,"MMM YY") -> Aug 18
A24: NA | B24: 1675 | C24: SW | D24: North Somerset | E24: DMP - Part 1 Sites & Policies | F24: DM | G24: 2 | H24: 42051 | J24: 42207 | M24: 42207 | O24: 42311 | Q24: 42312 | X24: 9.57 | Y24: 1.49 | AB24: 1.25 | AD24: 11.69 | AE24: =AllPlans[[#This Row],[Prep days*]]+AllPlans[[#This Row],[Hearing days*]]+AllPlans[[#This Row],[SV days*]]+AllPlans[[#This Row],[Travel days]]+AllPlans[[#This Row],[Reptg days*]] -> 24 | AG24: 42482 | AI24: 42471 | AK24: 42481 | AM24: 42481 | AO24: 42486 | AQ24: 42570 | AU24: SOU | AV24: 39.857143 | AW24: =SUM(AO24-Q24)/7 -> 24.857143 | AY24: E06000024 | AZ24: =TEXT(J24,"MMM YY") -> Jul 15 | BA24: =TEXT(AO24,"MMM YY") -> Apr 16
A25: NA | B25: 1367 | C25: EM | D25: North Northamptonshire | E25: Joint Core Strategy | F25: LP | G25: 3 | H25: 42030 | J25: 42216 | M25: 42216 | O25: 42325 | Q25: 42335 | X25: 28 | Y25: 7.56 | AB25: 1.99 | AD25: 31.5 | AE25: =AllPlans[[#This Row],[Prep days*]]+AllPlans[[#This Row],[Hearing days*]]+AllPlans[[#This Row],[SV days*]]+AllPlans[[#This Row],[Travel days]]+AllPlans[[#This Row],[Reptg days*]] -> 69.05 | AG25: 42524 | AI25: 42510 | AK25: 42521 | AM25: 42522 | AO25: 42543 | AQ25: 42565 | AU25: SOU | AV25: 46.714286 | AW25: =SUM(AO25-Q25)/7 -> 29.714286 | AY25: JSP019 | AZ25: =TEXT(J25,"MMM YY") -> Jul 15 | BA25: =TEXT(AO25,"MMM YY") -> Jun 16
A26: NA | B26: 1647 | C26: SW | D26: West Somerset | E26: Local Plan | F26: LP | G26: 3 | H26: 42045 | J26: 42216 | M26: 42216 | O26: 42443 | Q26: 42451 | X26: 29.66 | Y26: 4.04 | AB26: 1.08 | AD26: 13.91 | AE26: =AllPlans[[#This Row],[Prep days*]]+AllPlans[[#This Row],[Hearing days*]]+AllPlans[[#This Row],[SV days*]]+AllPlans[[#This Row],[Travel days]]+AllPlans[[#This Row],[Reptg days*]] -> 48.69 | AG26: 42615 | AI26: 42598 | AK26: 42612 | AM26: 42612 | AO26: 42627 | AQ26: 42697 | AU26: SOU | AV26: 58.714286 | AW26: =SUM(AO26-Q26)/7 -> 25.142857 | AY26: E07000191 | AZ26: =TEXT(J26,"MMM YY") -> Jul 15 | BA26: =TEXT(AO26,"MMM YY") -> Sep 16
A27: NA | B27: 1661 | C27: SW | D27: Wiltshire | E27: Chippenham AAP | F27: AAP | G27: 3 | H27: 42058 | J27: 42216 | M27: 42216 | O27: 42640 | Q27: 42647 | X27: 48.38 | Y27: 8.69 | AA27: 1.68 | AB27: 7.3 | AD27: 35 | AE27: =AllPlans[[#This Row],[Prep days*]]+AllPlans[[#This Row],[Hearing days*]]+AllPlans[[#This Row],[SV days*]]+AllPlans[[#This Row],[Travel days]]+AllPlans[[#This Row],[Reptg days*]] -> 101.05 | AG27: 42773 | AI27: 42752 | AK27: 42773 | AM27: 42773 | AO27: 42787 | AQ27: 42871 | AU27: SOU | AV27: 81.571429 | AW27: =SUM(AO27-Q27)/7 -> 20 | AY27: E06000054 | AZ27: =TEXT(J27,"MMM YY") -> Jul 15 | BA27: =TEXT(AO27,"MMM YY") -> Feb 17
A28: NA | B28: 1645 | C28: NW | D28: Sefton | E28: Local Plan | F28: LP | G28: 3 | H28: 42034 | J28: 42219 | M28: 42219 | O28: 42325 | Q28: 42676 | X28: 42.27 | Y28: 20.63 | AA28: 6.3 | AB28: 6.58 | AD28: 50.1 | AE28: =AllPlans[[#This Row],[Prep days*]]+AllPlans[[#This Row],[Hearing days*]]+AllPlans[[#This Row],[SV days*]]+AllPlans[[#This Row],[Travel days]]+AllPlans[[#This Row],[Reptg days*]] -> 125.88 | AG28: 42790 | AI28: 42766 | AK28: 42789 | AM28: 42789 | AO28: 42808 | AQ28: 42845 | AU28: SOU | AV28: 84.142857 | AW28: =SUM(AO28-Q28)/7 -> 18.857143 | AX28: HC Challenge email Legal 5/6 | AY28: E08000014 | AZ28: =TEXT(J28,"MMM YY") -> Aug 15 | BA28: =TEXT(AO28,"MMM YY") -> Mar 17
A29: NA | B29: 1596 | C29: SW | D29: Forest of Dean | E29: Allocations Plan | F29: SA | G29: 3 | H29: 42088 | J29: 42244 | M29: 42244 | O29: 42395 | Q29: 42930 | X29: 37.65 | Y29: 9.99 | AA29: 2.42 | AB29: 5.07 | AD29: 37.33 | AE29: =AllPlans[[#This Row],[Prep days*]]+AllPlans[[#This Row],[Hearing days*]]+AllPlans[[#This Row],[SV days*]]+AllPlans[[#This Row],[Travel days]]+AllPlans[[#This Row],[Reptg days*]] -> 92.46 | AG29: 43270 | AI29: 43242 | AK29: 43264 | AM29: 43265 | AO29: 43271 | AQ29: 43279 | AU29: SOU | AV29: =SUM(AO29-J29)/7 -> 146.71429 | AW29: =SUM(AO29-Q29)/7 -> 48.714286 | AY29: E07000080 | AZ29: =TEXT(J29,"MMM YY") -> Aug 15 | BA29: =TEXT(AO29,"MMM YY") -> Jun 18
A30: NA | B30: 1679 | C30: WM | D30: Wolverhampton | E30: City Centre AAP | F30: AAP | G30: 2 | H30: 42164 | J30: 42276 | M30: 42276 | O30: 42394 | Q30: 42394 | X30: 8.72 | Y30: 0.84 | AA30: 0.68 | AB30: 0.54 | AD30: 8.08 | AE30: =AllPlans[[#This Row],[Prep days*]]+AllPlans[[#This Row],[Hearing days*]]+AllPlans[[#This Row],[SV days*]]+AllPlans[[#This Row],[Travel days]]+AllPlans[[#This Row],[Reptg days*]] -> 18.86 | AG30: 42545 | AI30: 42521 | AK30: 42542 | AM30: 42542 | AO30: 42562 | AQ30: 42634 | AU30: SOU | AV30: 40.857143 | AW30: =SUM(AO30-Q30)/7 -> 24 | AY30: E08000031 | AZ30: =TEXT(J30,"MMM YY") -> Sep 15 | BA30: =TEXT(AO30,"MMM YY") -> Jul 16
A31: NA | B31: 1690 | C31: E | D31: Hertsmere | E31: Site Allocations & DM Policies | F31: SA | G31: 3 | H31: 42219 | J31: 42324 | M31: 42324 | O31: 42472 | Q31: 42474 | X31: 19.93 | Y31: 2.56 | AA31: 1.08 | AB31: 2.16 | AD31: 23.94 | AE31: =AllPlans[[#This Row],[Prep days*]]+AllPlans[[#This Row],[Hearing days*]]+AllPlans[[#This Row],[SV days*]]+AllPlans[[#This Row],[Travel days]]+AllPlans[[#This Row],[Reptg days*]] -> 49.67 | AG31: 42622 | AI31: 42600 | AK31: 42594 | AM31: 42616 | AO31: 42627 | AQ31: 42697 | AU31: SOU | AV31: 43.285714 | AW31: =SUM(AO31-Q31)/7 -> 21.857143 | AY31: E07000098 | AZ31: =TEXT(J31,"MMM YY") -> Nov 15 | BA31: =TEXT(AO31,"MMM YY") -> Sep 16
A32: NA | B32: 1682 | C32: YH | D32: Kingston upon Hull, City of | E32: Kingswood AAP | F32: AAP | G32: 2 | H32: 42173 | J32: 42338 | M32: 42338 | O32: 42423 | Q32: 42424 | X32: 14.8 | Y32: 1.76 | AB32: 0.68 | AD32: 12.23 | AE32: =AllPlans[[#This Row],[Prep days*]]+AllPlans[[#This Row],[Hearing days*]]+AllPlans[[#This Row],[SV days*]]+AllPlans[[#This Row],[Travel days]]+AllPlans[[#This Row],[Reptg days*]] -> 29.47 | AG32: 42531 | AI32: 42502 | AK32: 42515 | AM32: 42515 | AO32: 42521 | AQ32: 42628 | AU32: SOU | AV32: 26.142857 | AW32: =SUM(AO32-Q32)/7 -> 13.857143 | AY32: E06000010 | AZ32: =TEXT(J32,"MMM YY") -> Nov 15 | BA32: =TEXT(AO32,"MMM YY") -> May 16
A33: NA | B33: 1711 | C33: Lon | D33: Westminster | E33: Basement Revision | F33: PR | G33: 2 | H33: 42201 | J33: 42339 | M33: 42339 | O33: 42437 | Q33: 42437 | X33: 4.34 | Y33: 0.57 | AB33: 0.27 | AD33: 3.12 | AE33: =AllPlans[[#This Row],[Prep days*]]+AllPlans[[#This Row],[Hearing days*]]+AllPlans[[#This Row],[SV days*]]+AllPlans[[#This Row],[Travel days]]+AllPlans[[#This Row],[Reptg days*]] -> 8.3 | AG33: 42552 | AI33: 42536 | AK33: 42549 | AM33: 42549 | AO33: 42549 | AQ33: 42564 | AU33: SOU | AV33: 30 | AW33: =SUM(AO33-Q33)/7 -> 16 | AY33: E09000033 | AZ33: =TEXT(J33,"MMM YY") -> Dec 15 | BA33: =TEXT(AO33,"MMM YY") -> Jun 16
A34: NA | B34: 1712 | C34: Lon | D34: Westminster | E34: Mixed Use Revision | F34: PR | G34: 2 | H34: 42201 | J34: 42339 | M34: 42339 | O34: 42438 | Q34: 42438 | X34: 4.17 | Y34: 0.61 | AB34: 0.27 | AD34: 3.71 | AE34: =AllPlans[[#This Row],[Prep days*]]+AllPlans[[#This Row],[Hearing days*]]+AllPlans[[#This Row],[SV days*]]+AllPlans[[#This Row],[Travel days]]+AllPlans[[#This Row],[Reptg days*]] -> 8.76 | AG34: 42552 | AI34: 42536 | AK34: 42549 | AM34: 42549 | AO34: 42549 | AQ34: 42564 | AU34: SOU | AV34: 30 | AW34: =SUM(AO34-Q34)/7 -> 15.857143 | AY34: E09000033 | AZ34: =TEXT(J34,"MMM YY") -> Dec 15 | BA34: =TEXT(AO34,"MMM YY") -> Jun 16
A35: NA | B35: 1702 | C35: Lon | D35: Newham | E35: Detailed Sites & Policies | F35: SA | G35: 3 | H35: 42272 | J35: 42349 | M35: 42352 | O35: 42486 | Q35: 42495 | X35: 19.59 | Y35: 2.97 | AB35: 1.9 | AD35: 27.11 | AE35: =AllPlans[[#This Row],[Prep days*]]+AllPlans[[#This Row],[Hearing days*]]+AllPlans[[#This Row],[SV days*]]+AllPlans[[#This Row],[Travel days]]+AllPlans[[#This Row],[Reptg days*]] -> 51.57 | AG35: 42622 | AI35: 42612 | AK35: 42618 | AM35: 42618 | AO35: 42625 | AQ35: 42663 | AU35: SOU | AV35: 39.428571 | AW35: =SUM(AO35-Q35)/7 -> 18.571429 | AY35: E09000025 | AZ35: =TEXT(J35,"MMM YY") -> Dec 15 | BA35: =TEXT(AO35,"MMM YY") -> Sep 16
A36: NA | B36: 1531 | C36: E | D36: Ipswich | E36: Core Strategy & Policies | F36: LP | G36: 3 | H36: 41985 | J36: 42352 | M36: 42352 | O36: 42451 | Q36: 42550 | X36: 13.47 | Y36: 4.02 | AB36: 2.87 | AD36: 25.2 | AE36: =AllPlans[[#This Row],[Prep days*]]+AllPlans[[#This Row],[Hearing days*]]+AllPlans[[#This Row],[SV days*]]+AllPlans[[#This Row],[Travel days]]+AllPlans[[#This Row],[Reptg days*]] -> 45.56 | AG36: 42755 | AI36: 42733 | AK36: 42746 | AM36: 42746 | AO36: 42752 | AQ36: 42788 | AU36: SOU | AV36: 57.142857 | AW36: =SUM(AO36-Q36)/7 -> 28.857143 | AY36: E07000202 | AZ36: =TEXT(J36,"MMM YY") -> Dec 15 | BA36: =TEXT(AO36,"MMM YY") -> Jan 17
A37: NA | B37: 868 | C37: E | D37: Ipswich | E37: Site Allocations + IP1 AAP | F37: SA | G37: 3 | H37: 41985 | J37: 42352 | M37: 42352 | O37: 42556 | Q37: 42572 | X37: 14.31 | Y37: 5.4 | AB37: 3.55 | AD37: 15.75 | AE37: =AllPlans[[#This Row],[Prep days*]]+AllPlans[[#This Row],[Hearing days*]]+AllPlans[[#This Row],[SV days*]]+AllPlans[[#This Row],[Travel days]]+AllPlans[[#This Row],[Reptg days*]] -> 39.01 | AG37: 42755 | AI37: 42733 | AK37: 42746 | AM37: 42746 | AO37: 42752 | AQ37: 42788 | AU37: SOU | AV37: 57.142857 | AW37: =SUM(AO37-Q37)/7 -> 25.714286 | AY37: E07000202 | AZ37: =TEXT(J37,"MMM YY") -> Dec 15 | BA37: =TEXT(AO37,"MMM YY") -> Jan 17
A38: NA | B38: 1693 | C38: EM | D38: Derby | E38: Local Plan part 1 Core Strategy | F38: LP | G38: 3 | H38: 42242 | J38: 42356 | M38: 42356 | O38: 42486 | Q38: 42495 | X38: 25.37 | Y38: 4.09 | AA38: 2.17 | AB38: 3.02 | AD38: 22.59 | AE38: =AllPlans[[#This Row],[Prep days*]]+AllPlans[[#This Row],[Hearing days*]]+AllPlans[[#This Row],[SV days*]]+AllPlans[[#This Row],[Travel days]]+AllPlans[[#This Row],[Reptg days*]] -> 57.24 | AG38: 42699 | AI38: 42678 | AK38: 42692 | AM38: 42695 | AO38: 42709 | AQ38: 42760 | AU38: SOU | AV38: 50.428571 | AW38: =SUM(AO38-Q38)/7 -> 30.571429 | AY38: E06000015 | AZ38: =TEXT(J38,"MMM YY") -> Dec 15 | BA38: =TEXT(AO38,"MMM YY") -> Dec 16
A39: NA | B39: 1706 | C39: NW | D39: Eden | E39: Local Plan 2014-2032 | F39: LP | G39: 3 | H39: 42283 | J39: 42361 | M39: 42361 | O39: 42499 | Q39: 42859 | X39: 30.28 | Y39: 11.77 | AA39: 4.68 | AB39: 6.5 | AD39: 51.51 | AE39: =AllPlans[[#This Row],[Prep days*]]+AllPlans[[#This Row],[Hearing days*]]+AllPlans[[#This Row],[SV days*]]+AllPlans[[#This Row],[Travel days]]+AllPlans[[#This Row],[Reptg days*]] -> 104.74 | AG39: 43259 | AI39: 43252 | AK39: 43257 | AM39: 43257 | AO39: 43342 | AQ39: 43384 | AU39: SOU | AV39: =SUM(AO39-J39)/7 -> 140.14286 | AW39: =SUM(AO39-Q39)/7 -> 69 | AY39: E07000030 | AZ39: =TEXT(J39,"MMM YY") -> Dec 15 | BA39: =TEXT(AO39,"MMM YY") -> Aug 18
A40: NA | B40: 1696 | C40: SE | D40: Oxfordshire CC | E40: Minerals & Waste Local Plan -part 1 Core Strategy | F40: M&W | G40: 3 | H40: 42235 | J40: 42368 | M40: 42368 | O40: 42633 | Q40: 42643 | X40: 28.37 | Y40: 5.43 | AB40: 1.62 | AD40: 22.26 | AE40: =AllPlans[[#This Row],[Prep days*]]+AllPlans[[#This Row],[Hearing days*]]+AllPlans[[#This Row],[SV days*]]+AllPlans[[#This Row],[Travel days]]+AllPlans[[#This Row],[Reptg days*]] -> 57.68 | AG40: 42865 | AI40: 42832 | AK40: 42845 | AM40: 42859 | AO40: 42901 | AQ40: 42990 | AU40: SOU | AV40: 76.142857 | AW40: =SUM(AO40-Q40)/7 -> 36.857143 | AY40: E10000025 | AZ40: =TEXT(J40,"MMM YY") -> Dec 15 | BA40: =TEXT(AO40,"MMM YY") -> Jun 17
...

Sheet Key
A1: Key
B2: Plan Completed/Finished | E2: NOTE: PLANS SUBMITTED FROM 25/10/2021 ONWARDS HAVE WORKSTAGE TIME COMPLETED AS PER INSPECTOR TIMESHEET DATA (NOT BASED ON INVOICES)
B3: Live Plan
B4: Withdrawn
B5: Plan Unsound

Sheet LPA Lookup
A1: ONSLPA | B1: ONSCode
A2: Aberdeen City | B2: S12000033
A3: Aberdeenshire | B3: S12000034
A4: Adur | B4: E07000223
A5: Allerdale | B5: E07000026
A6: Amber Valley | B6: E07000032
A7: Angus | B7: S12000041
A8: Antrim and Newtownabbey | B8: N09000001
A9: Ards and North Down | B9: N09000011
A10: Argyll and Bute | B10: S12000035
A11: Armagh City, Banbridge and Craigavon | B11: N09000002
A12: Arun | B12: E07000224
... A410: Yorkshire Dales National Park | B410: E26000012
A411: =C411&" CC" -> Buckinghamshire CC | B411: E10000002 | C411: Buckinghamshire
A412: =C412&" CC" -> Cambridgeshire CC | B412: E10000003 | C412: Cambridgeshire
A413: =C413&" CC" -> Cumbria CC | B413: E10000006 | C413: Cumbria
A414: =C414&" CC" -> Derbyshire CC | B414: E10000007 | C414: Derbyshire
A415: =C415&" CC" -> Devon CC | B415: E10000008 | C415: Devon
A416: =C416&" CC" -> Dorset CC | B416: E10000009 | C416: Dorset
A417: =C417&" CC" -> East Sussex CC | B417: E10000011 | C417: East Sussex
A418: =C418&" CC" -> Essex CC | B418: E10000012 | C418: Essex
A419: =C419&" CC" -> Gloucestershire CC | B419: E10000013 | C419: Gloucestershire
A420: =C420&" CC" -> Hampshire CC | B420: E10000014 | C420: Hampshire
A421: =C421&" CC" -> Hertfordshire CC | B421: E10000015 | C421: Hertfordshire
A422: =C422&" CC" -> Kent CC | B422: E10000016 | C422: Kent
... A437: =C437&" CC" -> Worcestershire CC | B437: E10000034 | C437: Worcestershire
A438: Babergh & Mid Suffolk | B438: JSP033 | C438: =A438&D438 -> Babergh & Mid Suffolk1966 | D438: 1966 | E438: =B438 -> JSP033
A439: Central Lancashire | B439: JSP002 | C439: =A439&D439 -> Central Lancashire842 | D439: 842 | E439: =B439 -> JSP002
A440: Central Lincolnshire | B440: JSP003 | C440: =A440&D440 -> Central Lincolnshire1753 | D440: 1753 | E440: =B440 -> JSP003
A441: Central Lincolnshire | B441: JSP031 | C441: =A441&D441 -> Central Lincolnshire1486 | D441: 1486 | E441: =B441 -> JSP031
A442: Chiltern and South Bucks | B442: JSP014 | C442: =A442&D442 -> Chiltern and South Bucks1940 | D442: 1940 | E442: =B442 -> JSP014
A443: Christchurch and East Dorset | B443: JSP014 | C443: =A443&D443 -> Christchurch and East Dorset398 | D443: 398 | E443: =B443 -> JSP014
A444: Devon JSP | B444: JSP005 | C444: =A444&D444 -> Devon JSP | E444: =B444 -> JSP005
A445: East Hampshire and South Downs National Park | B445: JSP006 | C445: =A445&D445 -> East Hampshire and South Downs National Park919 | D445: 919 | E445: =B445 -> JSP006
A446: Gloucester, Cheltenham and Tewkesbury | B446: JSP008 | C446: =A446&D446 -> Gloucester, Cheltenham and Tewkesbury1109 | D446: 1109 | E446: =B446 -> JSP008
A447: Gloucester, Cheltenham and Tewkesbury | B447: JSP026 | C447: =A447&D447 -> Gloucester, Cheltenham and Tewkesbury | E447: =B447 -> JSP026
A448: Greater Manchester Spatial | B448: JSP009 | C448: =A448&D448 -> Greater Manchester Spatial | E448: =B448 -> JSP009
A449: Greater Norwich Partnership | B449: JSP010 | C449: =A449&D449 -> Greater Norwich Partnership1055 | D449: 1055 | E449: =B449 -> JSP010
A450: Greater Norwich Partnership | B450: JSP011 | C450: =A450&D450 -> Greater Norwich Partnership1350 | D450: 1350 | E450: =B450 -> JSP011
A451: Greater Nottingham Aligned | B451: JSP012 | C451: =A451&D451 -> Greater Nottingham Aligned1052 | D451: 1052 | E451: =B451 -> JSP012
...

Sheet LPA
A1: LPA Code | B1: LPA Country | C1: LPA County | D1: LPA Governmental Office | E1: Average of LPA Latitude | F1: LPA Location | G1: Average of LPA Longitude | H1: LPA Name
A2: A0665 | B2: England | C2: Cheshire | D2: North West | E2: 53.163361 | F2: Cheshire, England | G2: -2.70298 | H2: Cheshire West and Chester
A3: A1015 | B3: England | C3: Derbyshire | D3: East Midlands | E3: 53.255749 | F3: Derbyshire, England | G3: -1.40115 | H3: Chesterfield Borough Council
A4: A1530 | B4: England | C4: Essex | D4: East of England | E4: 51.87701 | F4: Essex, England | G4: 0.85977602 | H4: Colchester Borough Council
A5: A1720 | B5: England | C5: Hampshire | D5: South East | E5: 50.853931 | F5: Hampshire, England | G5: -1.23742 | H5: Fareham Borough Council
A6: A1910 | B6: England | C6: Hertfordshire | D6: East of England | E6: 51.768452 | F6: Hertfordshire, England | G6: -0.55097997 | H6: Dacorum Borough Council
A7: A2280 | B7: England | C7: Kent | D7: South East | E7: 51.447708 | F7: Kent, England | G7: 0.563173 | H7: Medway Council
A8: A2335 | B8: England | C8: Lancashire | D8: North West | E8: 54.056198 | F8: Lancashire, England | G8: -2.6944499 | H8: Lancaster City Council
A9: A2470 | B9: England | C9: Leicestershire | D9: East Midlands | E9: 52.667648 | F9: Leicestershire, England | G9: -0.62629998 | H9: Rutland County Council
A10: A2525 | B10: England | C10: Lincolnshire | D10: East Midlands | E10: 52.787579 | F10: Lincolnshire, England | G10: -0.030579999 | H10: South Holland District Council
A11: A3010 | B11: England | C11: Nottinghamshire | D11: East Midlands | E11: 53.356041 | F11: Nottinghamshire, England | G11: -0.97869998 | H11: Bassetlaw District Council
A12: A3655 | B12: England | C12: Surrey | D12: South East | E12: 51.308369 | F12: Surrey, England | G12: -0.57981998 | H12: Woking Borough Council
A13: A4520 | B13: England | C13: Tyne And Wear | D13: North East | E13: 54.969879 | F13: Tyne And Wear, England | G13: -1.44696 | H13: South Tyneside Council
... A360: Z6950 | B360: Wales | C360: NA | D360: NA | E360: 51.44838 | F360: NA, Wales | G360: -3.39803 | H360: Vale of Glamorgan County Borough Council

Sheet MiPINS-SQL
A1: Category | B1: Type | C1: Procedure | D1: LPA Code | E1: LPA name | F1: appeal_reference_number | G1: Rejected or Withdrawn | H1: appeal_withdrawn_date | I1: Visit type | J1: Appellant | K1: site_address_postcode | L1: Revieved date | M1: Valid date | N1: Start Date | O1: Event Date | P1: Decision Date | Q1: Decision | R1: Open or closed | S1: linked | T1: Level
A2: =IF(ISBLANK('Master Submitted DPDs'!#REF!),"","Local Plans") -> Local Plans | B2: =IF(ISBLANK('Master Submitted DPDs'!#REF!),"",'Master Submitted DPDs'!#REF!) -> #REF! | C2: =IF(ISBLANK('Master Submitted DPDs'!#REF!),"","IH") -> IH | D2: =LOOKUP($F2,'fuzzy LPA lookup'!$E:$E,'fuzzy LPA lookup'!$A:$A) -> #REF! | E2: =LOOKUP($F2,'fuzzy LPA lookup'!$E:$E,'fuzzy LPA lookup'!$D:$D) -> #REF! | F2: =IF(ISBLANK('Master Submitted DPDs'!#REF!),"",'Master Submitted DPDs'!#REF!) -> #REF! | G2: =IF(ISBLANK('Master Submitted DPDs'!#REF!),"","Withdrawn") -> Withdrawn | H2: =IF(ISBLANK('Master Submitted DPDs'!#REF!),"",'Master Submitted DPDs'!#REF!) -> #REF! | L2: =IF(ISBLANK('Master Submitted DPDs'!#REF!),"",'Master Submitted DPDs'!#REF!) -> #REF! | M2: =L2 -> #REF! | N2: =IF(ISBLANK('Master Submitted DPDs'!#REF!),IF(ISBLANK('Master Submitted DPDs'!#REF!),"",'Master Submitted DPDs'!#REF!),'Master Submitted DPDs'!#REF!) -> #REF! | O2: =IF(ISBLANK('Master Submitted DPDs'!#REF!),"",'Master Submitted DPDs'!#REF!) -> #REF! | P2: =IF(ISBLANK('Master Submitted DPDs'!#REF!),"",'Master Submitted DPDs'!#REF!) -> #REF! | Q2: =IF(ISBLANK('Master Submitted DPDs'!#REF!),"",'Master Submitted DPDs'!#REF!) -> #REF! | R2: =IF(F2="","",IF(AND(H2="",Q2<>"UNS",P2=""),"Open","Closed")) -> #REF! | T2: =IF(ISBLANK('Master Submitted DPDs'!#REF!),"",'Master Submitted DPDs'!#REF!) -> #REF!
A3: =IF(ISBLANK('Master Submitted DPDs'!#REF!),"","Local Plans") -> Local Plans | B3: =IF(ISBLANK('Master Submitted DPDs'!#REF!),"",'Master Submitted DPDs'!#REF!) -> #REF! | C3: =IF(ISBLANK('Master Submitted DPDs'!#REF!),"","IH") -> IH | D3: =LOOKUP($F3,'fuzzy LPA lookup'!$E:$E,'fuzzy LPA lookup'!$A:$A) -> #REF! | E3: =LOOKUP($F3,'fuzzy LPA lookup'!$E:$E,'fuzzy LPA lookup'!$D:$D) -> #REF! | F3: =IF(ISBLANK('Master Submitted DPDs'!#REF!),"",'Master Submitted DPDs'!#REF!) -> #REF! | G3: =IF(ISBLANK('Master Submitted DPDs'!#REF!),"","Withdrawn") -> Withdrawn | H3: =IF(ISBLANK('Master Submitted DPDs'!#REF!),"",'Master Submitted DPDs'!#REF!) -> #REF! | L3: =IF(ISBLANK('Master Submitted DPDs'!#REF!),"",'Master Submitted DPDs'!#REF!) -> #REF! | M3: =L3 -> #REF! | N3: =IF(ISBLANK('Master Submitted DPDs'!#REF!),IF(ISBLANK('Master Submitted DPDs'!#REF!),"",'Master Submitted DPDs'!#REF!),'Master Submitted DPDs'!#REF!) -> #REF! | O3: =IF(ISBLANK('Master Submitted DPDs'!#REF!),"",'Master Submitted DPDs'!#REF!) -> #REF! | P3: =IF(ISBLANK('Master Submitted DPDs'!#REF!),"",'Master Submitted DPDs'!#REF!) -> #REF! | Q3: =IF(ISBLANK('Master Submitted DPDs'!#REF!),"",'Master Submitted DPDs'!#REF!) -> #REF! | R3: =IF(F3="","",IF(AND(H3="",Q3<>"UNS",P3=""),"Open","Closed")) -> #REF! | T3: =IF(ISBLANK('Master Submitted DPDs'!#REF!),"",'Master Submitted DPDs'!#REF!) -> #REF!
A4: =IF(ISBLANK('Master Submitted DPDs'!#REF!),"","Local Plans") -> Local Plans | B4: =IF(ISBLANK('Master Submitted DPDs'!#REF!),"",'Master Submitted DPDs'!#REF!) -> #REF! | C4: =IF(ISBLANK('Master Submitted DPDs'!#REF!),"","IH") -> IH | D4: =LOOKUP($F4,'fuzzy LPA lookup'!$E:$E,'fuzzy LPA lookup'!$A:$A) -> #REF! | E4: =LOOKUP($F4,'fuzzy LPA lookup'!$E:$E,'fuzzy LPA lookup'!$D:$D) -> #REF! | F4: =IF(ISBLANK('Master Submitted DPDs'!#REF!),"",'Master Submitted DPDs'!#REF!) -> #REF! | G4: =IF(ISBLANK('Master Submitted DPDs'!#REF!),"","Withdrawn") -> Withdrawn | H4: =IF(ISBLANK('Master Submitted DPDs'!#REF!),"",'Master Submitted DPDs'!#REF!) -> #REF! | L4: =IF(ISBLANK('Master Submitted DPDs'!#REF!),"",'Master Submitted DPDs'!#REF!) -> #REF! | M4: =L4 -> #REF! | N4: =IF(ISBLANK('Master Submitted DPDs'!#REF!),IF(ISBLANK('Master Submitted DPDs'!#REF!),"",'Master Submitted DPDs'!#REF!),'Master Submitted DPDs'!#REF!) -> #REF! | O4: =IF(ISBLANK('Master Submitted DPDs'!#REF!),"",'Master Submitted DPDs'!#REF!) -> #REF! | P4: =IF(ISBLANK('Master Submitted DPDs'!#REF!),"",'Master Submitted DPDs'!#REF!) -> #REF! | Q4: =IF(ISBLANK('Master Submitted DPDs'!#REF!),"",'Master Submitted DPDs'!#REF!) -> #REF! | R4: =IF(F4="","",IF(AND(H4="",Q4<>"UNS",P4=""),"Open","Closed")) -> #REF! | T4: =IF(ISBLANK('Master Submitted DPDs'!#REF!),"",'Master Submitted DPDs'!#REF!) -> #REF!
A5: =IF(ISBLANK('Master Submitted DPDs'!#REF!),"","Local Plans") -> Local Plans | B5: =IF(ISBLANK('Master Submitted DPDs'!#REF!),"",'Master Submitted DPDs'!#REF!) -> #REF! | C5: =IF(ISBLANK('Master Submitted DPDs'!#REF!),"","IH") -> IH | D5: =LOOKUP($F5,'fuzzy LPA lookup'!$E:$E,'fuzzy LPA lookup'!$A:$A) -> #REF! | E5: =LOOKUP($F5,'fuzzy LPA lookup'!$E:$E,'fuzzy LPA lookup'!$D:$D) -> #REF! | F5: =IF(ISBLANK('Master Submitted DPDs'!#REF!),"",'Master Submitted DPDs'!#REF!) -> #REF! | G5: =IF(ISBLANK('Master Submitted DPDs'!#REF!),"","Withdrawn") -> Withdrawn | H5: =IF(ISBLANK('Master Submitted DPDs'!#REF!),"",'Master Submitted DPDs'!#REF!) -> #REF! | L5: =IF(ISBLANK('Master Submitted DPDs'!#REF!),"",'Master Submitted DPDs'!#REF!) -> #REF! | M5: =L5 -> #REF! | N5: =IF(ISBLANK('Master Submitted DPDs'!#REF!),IF(ISBLANK('Master Submitted DPDs'!#REF!),"",'Master Submitted DPDs'!#REF!),'Master Submitted DPDs'!#REF!) -> #REF! | O5: =IF(ISBLANK('Master Submitted DPDs'!#REF!),"",'Master Submitted DPDs'!#REF!) -> #REF! | P5: =IF(ISBLANK('Master Submitted DPDs'!#REF!),"",'Master Submitted DPDs'!#REF!) -> #REF! | Q5: =IF(ISBLANK('Master Submitted DPDs'!#REF!),"",'Master Submitted DPDs'!#REF!) -> #REF! | R5: =IF(F5="","",IF(AND(H5="",Q5<>"UNS",P5=""),"Open","Closed")) -> #REF! | T5: =IF(ISBLANK('Master Submitted DPDs'!#REF!),"",'Master Submitted DPDs'!#REF!) -> #REF!
A6: =IF(ISBLANK('Master Submitted DPDs'!#REF!),"","Local Plans") -> Local Plans | B6: =IF(ISBLANK('Master Submitted DPDs'!#REF!),"",'Master Submitted DPDs'!#REF!) -> #REF! | C6: =IF(ISBLANK('Master Submitted DPDs'!#REF!),"","IH") -> IH | D6: =LOOKUP($F6,'fuzzy LPA lookup'!$E:$E,'fuzzy LPA lookup'!$A:$A) -> #REF! | E6: =LOOKUP($F6,'fuzzy LPA lookup'!$E:$E,'fuzzy LPA lookup'!$D:$D) -> #REF! | F6: =IF(ISBLANK('Master Submitted DPDs'!#REF!),"",'Master Submitted DPDs'!#REF!) -> #REF! | G6: =IF(ISBLANK('Master Submitted DPDs'!#REF!),"","Withdrawn") -> Withdrawn | H6: =IF(ISBLANK('Master Submitted DPDs'!#REF!),"",'Master Submitted DPDs'!#REF!) -> #REF! | L6: =IF(ISBLANK('Master Submitted DPDs'!#REF!),"",'Master Submitted DPDs'!#REF!) -> #REF! | M6: =L6 -> #REF! | N6: =IF(ISBLANK('Master Submitted DPDs'!#REF!),IF(ISBLANK('Master Submitted DPDs'!#REF!),"",'Master Submitted DPDs'!#REF!),'Master Submitted DPDs'!#REF!) -> #REF! | O6: =IF(ISBLANK('Master Submitted DPDs'!#REF!),"",'Master Submitted DPDs'!#REF!) -> #REF! | P6: =IF(ISBLANK('Master Submitted DPDs'!#REF!),"",'Master Submitted DPDs'!#REF!) -> #REF! | Q6: =IF(ISBLANK('Master Submitted DPDs'!#REF!),"",'Master Submitted DPDs'!#REF!) -> #REF! | R6: =IF(F6="","",IF(AND(H6="",Q6<>"UNS",P6=""),"Open","Closed")) -> #REF! | T6: =IF(ISBLANK('Master Submitted DPDs'!#REF!),"",'Master Submitted DPDs'!#REF!) -> #REF!
A7: =IF(ISBLANK('Master Submitted DPDs'!#REF!),"","Local Plans") -> Local Plans | B7: =IF(ISBLANK('Master Submitted DPDs'!#REF!),"",'Master Submitted DPDs'!#REF!) -> #REF! | C7: =IF(ISBLANK('Master Submitted DPDs'!#REF!),"","IH") -> IH | D7: =LOOKUP($F7,'fuzzy LPA lookup'!$E:$E,'fuzzy LPA lookup'!$A:$A) -> #REF! | E7: =LOOKUP($F7,'fuzzy LPA lookup'!$E:$E,'fuzzy LPA lookup'!$D:$D) -> #REF! | F7: =IF(ISBLANK('Master Submitted DPDs'!#REF!),"",'Master Submitted DPDs'!#REF!) -> #REF! | G7: =IF(ISBLANK('Master Submitted DPDs'!#REF!),"","Withdrawn") -> Withdrawn | H7: =IF(ISBLANK('Master Submitted DPDs'!#REF!),"",'Master Submitted DPDs'!#REF!) -> #REF! | L7: =IF(ISBLANK('Master Submitted DPDs'!#REF!),"",'Master Submitted DPDs'!#REF!) -> #REF! | M7: =L7 -> #REF! | N7: =IF(ISBLANK('Master Submitted DPDs'!#REF!),IF(ISBLANK('Master Submitted DPDs'!#REF!),"",'Master Submitted DPDs'!#REF!),'Master Submitted DPDs'!#REF!) -> #REF! | O7: =IF(ISBLANK('Master Submitted DPDs'!#REF!),"",'Master Submitted DPDs'!#REF!) -> #REF! | P7: =IF(ISBLANK('Master Submitted DPDs'!#REF!),"",'Master Submitted DPDs'!#REF!) -> #REF! | Q7: =IF(ISBLANK('Master Submitted DPDs'!#REF!),"",'Master Submitted DPDs'!#REF!) -> #REF! | R7: =IF(F7="","",IF(AND(H7="",Q7<>"UNS",P7=""),"Open","Closed")) -> #REF! | T7: =IF(ISBLANK('Master Submitted DPDs'!#REF!),"",'Master Submitted DPDs'!#REF!) -> #REF!
A8: =IF(ISBLANK('Master Submitted DPDs'!#REF!),"","Local Plans") -> Local Plans | B8: =IF(ISBLANK('Master Submitted DPDs'!#REF!),"",'Master Submitted DPDs'!#REF!) -> #REF! | C8: =IF(ISBLANK('Master Submitted DPDs'!#REF!),"","IH") -> IH | D8: =LOOKUP($F8,'fuzzy LPA lookup'!$E:$E,'fuzzy LPA lookup'!$A:$A) -> #REF! | E8: =LOOKUP($F8,'fuzzy LPA lookup'!$E:$E,'fuzzy LPA lookup'!$D:$D) -> #REF! | F8: =IF(ISBLANK('Master Submitted DPDs'!#REF!),"",'Master Submitted DPDs'!#REF!) -> #REF! | G8: =IF(ISBLANK('Master Submitted DPDs'!#REF!),"","Withdrawn") -> Withdrawn | H8: =IF(ISBLANK('Master Submitted DPDs'!#REF!),"",'Master Submitted DPDs'!#REF!) -> #REF! | L8: =IF(ISBLANK('Master Submitted DPDs'!#REF!),"",'Master Submitted DPDs'!#REF!) -> #REF! | M8: =L8 -> #REF! | N8: =IF(ISBLANK('Master Submitted DPDs'!#REF!),IF(ISBLANK('Master Submitted DPDs'!#REF!),"",'Master Submitted DPDs'!#REF!),'Master Submitted DPDs'!#REF!) -> #REF! | O8: =IF(ISBLANK('Master Submitted DPDs'!#REF!),"",'Master Submitted DPDs'!#REF!) -> #REF! | P8: =IF(ISBLANK('Master Submitted DPDs'!#REF!),"",'Master Submitted DPDs'!#REF!) -> #REF! | Q8: =IF(ISBLANK('Master Submitted DPDs'!#REF!),"",'Master Submitted DPDs'!#REF!) -> #REF! | R8: =IF(F8="","",IF(AND(H8="",Q8<>"UNS",P8=""),"Open","Closed")) -> #REF! | T8: =IF(ISBLANK('Master Submitted DPDs'!#REF!),"",'Master Submitted DPDs'!#REF!) -> #REF!
A9: =IF(ISBLANK('Master Submitted DPDs'!#REF!),"","Local Plans") -> Local Plans | B9: =IF(ISBLANK('Master Submitted DPDs'!#REF!),"",'Master Submitted DPDs'!#REF!) -> #REF! | C9: =IF(ISBLANK('Master Submitted DPDs'!#REF!),"","IH") -> IH | D9: =LOOKUP($F9,'fuzzy LPA lookup'!$E:$E,'fuzzy LPA lookup'!$A:$A) -> #REF! | E9: =LOOKUP($F9,'fuzzy LPA lookup'!$E:$E,'fuzzy LPA lookup'!$D:$D) -> #REF! | F9: =IF(ISBLANK('Master Submitted DPDs'!#REF!),"",'Master Submitted DPDs'!#REF!) -> #REF! | G9: =IF(ISBLANK('Master Submitted DPDs'!#REF!),"","Withdrawn") -> Withdrawn | H9: =IF(ISBLANK('Master Submitted DPDs'!#REF!),"",'Master Submitted DPDs'!#REF!) -> #REF! | L9: =IF(ISBLANK('Master Submitted DPDs'!#REF!),"",'Master Submitted DPDs'!#REF!) -> #REF! | M9: =L9 -> #REF! | N9: =IF(ISBLANK('Master Submitted DPDs'!#REF!),IF(ISBLANK('Master Submitted DPDs'!#REF!),"",'Master Submitted DPDs'!#REF!),'Master Submitted DPDs'!#REF!) -> #REF! | O9: =IF(ISBLANK('Master Submitted DPDs'!#REF!),"",'Master Submitted DPDs'!#REF!) -> #REF! | P9: =IF(ISBLANK('Master Submitted DPDs'!#REF!),"",'Master Submitted DPDs'!#REF!) -> #REF! | Q9: =IF(ISBLANK('Master Submitted DPDs'!#REF!),"",'Master Submitted DPDs'!#REF!) -> #REF! | R9: =IF(F9="","",IF(AND(H9="",Q9<>"UNS",P9=""),"Open","Closed")) -> #REF! | T9: =IF(ISBLANK('Master Submitted DPDs'!#REF!),"",'Master Submitted DPDs'!#REF!) -> #REF!
A10: =IF(ISBLANK('Master Submitted DPDs'!#REF!),"","Local Plans") -> Local Plans | B10: =IF(ISBLANK('Master Submitted DPDs'!#REF!),"",'Master Submitted DPDs'!#REF!) -> #REF! | C10: =IF(ISBLANK('Master Submitted DPDs'!#REF!),"","IH") -> IH | D10: =LOOKUP($F10,'fuzzy LPA lookup'!$E:$E,'fuzzy LPA lookup'!$A:$A) -> #REF! | E10: =LOOKUP($F10,'fuzzy LPA lookup'!$E:$E,'fuzzy LPA lookup'!$D:$D) -> #REF! | F10: =IF(ISBLANK('Master Submitted DPDs'!#REF!),"",'Master Submitted DPDs'!#REF!) -> #REF! | G10: =IF(ISBLANK('Master Submitted DPDs'!#REF!),"","Withdrawn") -> Withdrawn | H10: =IF(ISBLANK('Master Submitted DPDs'!#REF!),"",'Master Submitted DPDs'!#REF!) -> #REF! | L10: =IF(ISBLANK('Master Submitted DPDs'!#REF!),"",'Master Submitted DPDs'!#REF!) -> #REF! | M10: =L10 -> #REF! | N10: =IF(ISBLANK('Master Submitted DPDs'!#REF!),IF(ISBLANK('Master Submitted DPDs'!#REF!),"",'Master Submitted DPDs'!#REF!),'Master Submitted DPDs'!#REF!) -> #REF! | O10: =IF(ISBLANK('Master Submitted DPDs'!#REF!),"",'Master Submitted DPDs'!#REF!) -> #REF! | P10: =IF(ISBLANK('Master Submitted DPDs'!#REF!),"",'Master Submitted DPDs'!#REF!) -> #REF! | Q10: =IF(ISBLANK('Master Submitted DPDs'!#REF!),"",'Master Submitted DPDs'!#REF!) -> #REF! | R10: =IF(F10="","",IF(AND(H10="",Q10<>"UNS",P10=""),"Open","Closed")) -> #REF! | T10: =IF(ISBLANK('Master Submitted DPDs'!#REF!),"",'Master Submitted DPDs'!#REF!) -> #REF!
A11: =IF(ISBLANK('Master Submitted DPDs'!#REF!),"","Local Plans") -> Local Plans | B11: =IF(ISBLANK('Master Submitted DPDs'!#REF!),"",'Master Submitted DPDs'!#REF!) -> #REF! | C11: =IF(ISBLANK('Master Submitted DPDs'!#REF!),"","IH") -> IH | D11: =LOOKUP($F11,'fuzzy LPA lookup'!$E:$E,'fuzzy LPA lookup'!$A:$A) -> #REF! | E11: =LOOKUP($F11,'fuzzy LPA lookup'!$E:$E,'fuzzy LPA lookup'!$D:$D) -> #REF! | F11: =IF(ISBLANK('Master Submitted DPDs'!#REF!),"",'Master Submitted DPDs'!#REF!) -> #REF! | G11: =IF(ISBLANK('Master Submitted DPDs'!#REF!),"","Withdrawn") -> Withdrawn | H11: =IF(ISBLANK('Master Submitted DPDs'!#REF!),"",'Master Submitted DPDs'!#REF!) -> #REF! | L11: =IF(ISBLANK('Master Submitted DPDs'!#REF!),"",'Master Submitted DPDs'!#REF!) -> #REF! | M11: =L11 -> #REF! | N11: =IF(ISBLANK('Master Submitted DPDs'!#REF!),IF(ISBLANK('Master Submitted DPDs'!#REF!),"",'Master Submitted DPDs'!#REF!),'Master Submitted DPDs'!#REF!) -> #REF! | O11: =IF(ISBLANK('Master Submitted DPDs'!#REF!),"",'Master Submitted DPDs'!#REF!) -> #REF! | P11: =IF(ISBLANK('Master Submitted DPDs'!#REF!),"",'Master Submitted DPDs'!#REF!) -> #REF! | Q11: =IF(ISBLANK('Master Submitted DPDs'!#REF!),"",'Master Submitted DPDs'!#REF!) -> #REF! | R11: =IF(F11="","",IF(AND(H11="",Q11<>"UNS",P11=""),"Open","Closed")) -> #REF! | T11: =IF(ISBLANK('Master Submitted DPDs'!#REF!),"",'Master Submitted DPDs'!#REF!) -> #REF!
A12: =IF(ISBLANK('Master Submitted DPDs'!#REF!),"","Local Plans") -> Local Plans | B12: =IF(ISBLANK('Master Submitted DPDs'!#REF!),"",'Master Submitted DPDs'!#REF!) -> #REF! | C12: =IF(ISBLANK('Master Submitted DPDs'!#REF!),"","IH") -> IH | D12: =LOOKUP($F12,'fuzzy LPA lookup'!$E:$E,'fuzzy LPA lookup'!$A:$A) -> #REF! | E12: =LOOKUP($F12,'fuzzy LPA lookup'!$E:$E,'fuzzy LPA lookup'!$D:$D) -> #REF! | F12: =IF(ISBLANK('Master Submitted DPDs'!#REF!),"",'Master Submitted DPDs'!#REF!) -> #REF! | G12: =IF(ISBLANK('Master Submitted DPDs'!#REF!),"","Withdrawn") -> Withdrawn | H12: =IF(ISBLANK('Master Submitted DPDs'!#REF!),"",'Master Submitted DPDs'!#REF!) -> #REF! | L12: =IF(ISBLANK('Master Submitted DPDs'!#REF!),"",'Master Submitted DPDs'!#REF!) -> #REF! | M12: =L12 -> #REF! | N12: =IF(ISBLANK('Master Submitted DPDs'!#REF!),IF(ISBLANK('Master Submitted DPDs'!#REF!),"",'Master Submitted DPDs'!#REF!),'Master Submitted DPDs'!#REF!) -> #REF! | O12: =IF(ISBLANK('Master Submitted DPDs'!#REF!),"",'Master Submitted DPDs'!#REF!) -> #REF! | P12: =IF(ISBLANK('Master Submitted DPDs'!#REF!),"",'Master Submitted DPDs'!#REF!) -> #REF! | Q12: =IF(ISBLANK('Master Submitted DPDs'!#REF!),"",'Master Submitted DPDs'!#REF!) -> #REF! | R12: =IF(F12="","",IF(AND(H12="",Q12<>"UNS",P12=""),"Open","Closed")) -> #REF! | T12: =IF(ISBLANK('Master Submitted DPDs'!#REF!),"",'Master Submitted DPDs'!#REF!) -> #REF!
A13: =IF(ISBLANK('Master Submitted DPDs'!#REF!),"","Local Plans") -> Local Plans | B13: =IF(ISBLANK('Master Submitted DPDs'!#REF!),"",'Master Submitted DPDs'!#REF!) -> #REF! | C13: =IF(ISBLANK('Master Submitted DPDs'!#REF!),"","IH") -> IH | D13: =LOOKUP($F13,'fuzzy LPA lookup'!$E:$E,'fuzzy LPA lookup'!$A:$A) -> #REF! | E13: =LOOKUP($F13,'fuzzy LPA lookup'!$E:$E,'fuzzy LPA lookup'!$D:$D) -> #REF! | F13: =IF(ISBLANK('Master Submitted DPDs'!#REF!),"",'Master Submitted DPDs'!#REF!) -> #REF! | G13: =IF(ISBLANK('Master Submitted DPDs'!#REF!),"","Withdrawn") -> Withdrawn | H13: =IF(ISBLANK('Master Submitted DPDs'!#REF!),"",'Master Submitted DPDs'!#REF!) -> #REF! | L13: =IF(ISBLANK('Master Submitted DPDs'!#REF!),"",'Master Submitted DPDs'!#REF!) -> #REF! | M13: =L13 -> #REF! | N13: =IF(ISBLANK('Master Submitted DPDs'!#REF!),IF(ISBLANK('Master Submitted DPDs'!#REF!),"",'Master Submitted DPDs'!#REF!),'Master Submitted DPDs'!#REF!) -> #REF! | O13: =IF(ISBLANK('Master Submitted DPDs'!#REF!),"",'Master Submitted DPDs'!#REF!) -> #REF! | P13: =IF(ISBLANK('Master Submitted DPDs'!#REF!),"",'Master Submitted DPDs'!#REF!) -> #REF! | Q13: =IF(ISBLANK('Master Submitted DPDs'!#REF!),"",'Master Submitted DPDs'!#REF!) -> #REF! | R13: =IF(F13="","",IF(AND(H13="",Q13<>"UNS",P13=""),"Open","Closed")) -> #REF! | T13: =IF(ISBLANK('Master Submitted DPDs'!#REF!),"",'Master Submitted DPDs'!#REF!) -> #REF!
... A679: =IF(ISBLANK('Master Submitted DPDs'!#REF!),"","Local Plans") -> Local Plans | B679: =IF(ISBLANK('Master Submitted DPDs'!#REF!),"",'Master Submitted DPDs'!#REF!) -> #REF! | C679: =IF(ISBLANK('Master Submitted DPDs'!#REF!),"","IH") -> IH | D679: =LOOKUP($F679,'fuzzy LPA lookup'!$E:$E,'fuzzy LPA lookup'!$A:$A) -> #REF! | E679: =LOOKUP($F679,'fuzzy LPA lookup'!$E:$E,'fuzzy LPA lookup'!$D:$D) -> #REF! | F679: =IF(ISBLANK('Master Submitted DPDs'!#REF!),"",'Master Submitted DPDs'!#REF!) -> #REF! | G679: =IF(ISBLANK('Master Submitted DPDs'!#REF!),"","Withdrawn") -> Withdrawn | H679: =IF(ISBLANK('Master Submitted DPDs'!#REF!),"",'Master Submitted DPDs'!#REF!) -> #REF! | L679: =IF(ISBLANK('Master Submitted DPDs'!#REF!),"",'Master Submitted DPDs'!#REF!) -> #REF! | M679: =L679 -> #REF! | N679: =IF(ISBLANK('Master Submitted DPDs'!#REF!),IF(ISBLANK('Master Submitted DPDs'!#REF!),"",'Master Submitted DPDs'!#REF!),'Master Submitted DPDs'!#REF!) -> #REF! | O679: =IF(ISBLANK('Master Submitted DPDs'!#REF!),"",'Master Submitted DPDs'!#REF!) -> #REF! | P679: =IF(ISBLANK('Master Submitted DPDs'!#REF!),"",'Master Submitted DPDs'!#REF!) -> #REF! | Q679: =IF(ISBLANK('Master Submitted DPDs'!#REF!),"",'Master Submitted DPDs'!#REF!) -> #REF! | R679: =IF(F679="","",IF(AND(H679="",Q679<>"UNS",P679=""),"Open","Closed")) -> #REF! | T679: =IF(ISBLANK('Master Submitted DPDs'!#REF!),"",'Master Submitted DPDs'!#REF!) -> #REF!
A680: =IF(ISBLANK('Master Submitted DPDs'!#REF!),"","Local Plans") -> Local Plans | B680: =IF(ISBLANK('Master Submitted DPDs'!F2),"",'Master Submitted DPDs'!F2) -> LP | C680: =IF(ISBLANK('Master Submitted DPDs'!$B2),"","IH") -> IH | D680: =LOOKUP($F680,'fuzzy LPA lookup'!$E:$E,'fuzzy LPA lookup'!$A:$A) -> T3725 | E680: =LOOKUP($F680,'fuzzy LPA lookup'!$E:$E,'fuzzy LPA lookup'!$D:$D) -> Warwick District Council | F680: =IF(ISBLANK('Master Submitted DPDs'!B2),"",'Master Submitted DPDs'!B2) -> 1570 | G680: =IF(ISBLANK('Master Submitted DPDs'!AS2),"","Withdrawn") | H680: =IF(ISBLANK('Master Submitted DPDs'!AS2),"",'Master Submitted DPDs'!AS2) | L680: =IF(ISBLANK('Master Submitted DPDs'!J2),"",'Master Submitted DPDs'!J2) -> 42034 | M680: =L680 -> 42034 | N680: =IF(ISBLANK('Master Submitted DPDs'!M2),IF(ISBLANK('Master Submitted DPDs'!O2),"",'Master Submitted DPDs'!O2),'Master Submitted DPDs'!M2) -> 42034 | O680: =IF(ISBLANK('Master Submitted DPDs'!Q2),"",'Master Submitted DPDs'!Q2) -> 42719 | P680: =IF(ISBLANK('Master Submitted DPDs'!AO2),"",'Master Submitted DPDs'!AO2) -> 42944 | Q680: =IF(ISBLANK('Master Submitted DPDs'!AU2),"",'Master Submitted DPDs'!AU2) -> SOU | R680: =IF(F680="","",IF(AND(H680="",Q680<>"UNS",P680=""),"Open","Closed")) -> Closed | T680: =IF(ISBLANK('Master Submitted DPDs'!G2),"",'Master Submitted DPDs'!G2) -> B
A681: =IF(ISBLANK('Master Submitted DPDs'!#REF!),"","Local Plans") -> Local Plans | B681: =IF(ISBLANK('Master Submitted DPDs'!F3),"",'Master Submitted DPDs'!F3) -> LP | C681: =IF(ISBLANK('Master Submitted DPDs'!$B3),"","IH") -> IH | D681: =LOOKUP($F681,'fuzzy LPA lookup'!$E:$E,'fuzzy LPA lookup'!$A:$A) -> X1355 | E681: =LOOKUP($F681,'fuzzy LPA lookup'!$E:$E,'fuzzy LPA lookup'!$D:$D) -> Durham County Council | F681: =IF(ISBLANK('Master Submitted DPDs'!B3),"",'Master Submitted DPDs'!B3) -> 1089 | G681: =IF(ISBLANK('Master Submitted DPDs'!AS3),"","Withdrawn") | H681: =IF(ISBLANK('Master Submitted DPDs'!AS3),"",'Master Submitted DPDs'!AS3) | L681: =IF(ISBLANK('Master Submitted DPDs'!J3),"",'Master Submitted DPDs'!J3) -> 42034 | M681: =L681 -> 42034 | N681: =IF(ISBLANK('Master Submitted DPDs'!M3),IF(ISBLANK('Master Submitted DPDs'!O3),"",'Master Submitted DPDs'!O3),'Master Submitted DPDs'!M3) -> 42034 | O681: =IF(ISBLANK('Master Submitted DPDs'!Q3),"",'Master Submitted DPDs'!Q3) -> 43006 | P681: =IF(ISBLANK('Master Submitted DPDs'!AO3),"",'Master Submitted DPDs'!AO3) -> 43285 | Q681: =IF(ISBLANK('Master Submitted DPDs'!AU3),"",'Master Submitted DPDs'!AU3) -> SOU | R681: =IF(F681="","",IF(AND(H681="",Q681<>"UNS",P681=""),"Open","Closed")) -> Closed | T681: =IF(ISBLANK('Master Submitted DPDs'!G3),"",'Master Submitted DPDs'!G3) -> A
A682: =IF(ISBLANK('Master Submitted DPDs'!#REF!),"","Local Plans") -> Local Plans | B682: =IF(ISBLANK('Master Submitted DPDs'!F4),"",'Master Submitted DPDs'!F4) -> LP | C682: =IF(ISBLANK('Master Submitted DPDs'!$B4),"","IH") -> IH | D682: =LOOKUP($F682,'fuzzy LPA lookup'!$E:$E,'fuzzy LPA lookup'!$A:$A) -> M9584 | E682: =LOOKUP($F682,'fuzzy LPA lookup'!$E:$E,'fuzzy LPA lookup'!$D:$D) -> London Legacy Development Corporation | F682: =IF(ISBLANK('Master Submitted DPDs'!B4),"",'Master Submitted DPDs'!B4) -> 1617 | G682: =IF(ISBLANK('Master Submitted DPDs'!AS4),"","Withdrawn") | H682: =IF(ISBLANK('Master Submitted DPDs'!AS4),"",'Master Submitted DPDs'!AS4) | L682: =IF(ISBLANK('Master Submitted DPDs'!J4),"",'Master Submitted DPDs'!J4) -> 42040 | M682: =L682 -> 42040 | N682: =IF(ISBLANK('Master Submitted DPDs'!M4),IF(ISBLANK('Master Submitted DPDs'!O4),"",'Master Submitted DPDs'!O4),'Master Submitted DPDs'!M4) -> 42041 | O682: =IF(ISBLANK('Master Submitted DPDs'!Q4),"",'Master Submitted DPDs'!Q4) -> 42180 | P682: =IF(ISBLANK('Master Submitted DPDs'!AO4),"",'Master Submitted DPDs'!AO4) -> 42403 | Q682: =IF(ISBLANK('Master Submitted DPDs'!AU4),"",'Master Submitted DPDs'!AU4) -> SOU | R682: =IF(F682="","",IF(AND(H682="",Q682<>"UNS",P682=""),"Open","Closed")) -> Closed | T682: =IF(ISBLANK('Master Submitted DPDs'!G4),"",'Master Submitted DPDs'!G4) -> A
A683: =IF(ISBLANK('Master Submitted DPDs'!#REF!),"","Local Plans") -> Local Plans | B683: =IF(ISBLANK('Master Submitted DPDs'!F5),"",'Master Submitted DPDs'!F5) -> LP | C683: =IF(ISBLANK('Master Submitted DPDs'!$B5),"","IH") -> IH | D683: =LOOKUP($F683,'fuzzy LPA lookup'!$E:$E,'fuzzy LPA lookup'!$A:$A) -> H1033 | E683: =LOOKUP($F683,'fuzzy LPA lookup'!$E:$E,'fuzzy LPA lookup'!$D:$D) -> High Peak Borough Council | F683: =IF(ISBLANK('Master Submitted DPDs'!B5),"",'Master Submitted DPDs'!B5) -> 1435 | G683: =IF(ISBLANK('Master Submitted DPDs'!AS5),"","Withdrawn") | H683: =IF(ISBLANK('Master Submitted DPDs'!AS5),"",'Master Submitted DPDs'!AS5) | L683: =IF(ISBLANK('Master Submitted DPDs'!J5),"",'Master Submitted DPDs'!J5) -> 42040 | M683: =L683 -> 42040 | N683: =IF(ISBLANK('Master Submitted DPDs'!M5),IF(ISBLANK('Master Submitted DPDs'!O5),"",'Master Submitted DPDs'!O5),'Master Submitted DPDs'!M5) -> 42041 | O683: =IF(ISBLANK('Master Submitted DPDs'!Q5),"",'Master Submitted DPDs'!Q5) -> 42514 | P683: =IF(ISBLANK('Master Submitted DPDs'!AO5),"",'Master Submitted DPDs'!AO5) -> 42636 | Q683: =IF(ISBLANK('Master Submitted DPDs'!AU5),"",'Master Submitted DPDs'!AU5) -> SOU | R683: =IF(F683="","",IF(AND(H683="",Q683<>"UNS",P683=""),"Open","Closed")) -> Closed | T683: =IF(ISBLANK('Master Submitted DPDs'!G5),"",'Master Submitted DPDs'!G5) -> B
A684: =IF(ISBLANK('Master Submitted DPDs'!#REF!),"","Local Plans") -> Local Plans | B684: =IF(ISBLANK('Master Submitted DPDs'!F6),"",'Master Submitted DPDs'!F6) -> AAP | C684: =IF(ISBLANK('Master Submitted DPDs'!$B6),"","IH") -> IH | D684: =LOOKUP($F684,'fuzzy LPA lookup'!$E:$E,'fuzzy LPA lookup'!$A:$A) -> M9584 | E684: =LOOKUP($F684,'fuzzy LPA lookup'!$E:$E,'fuzzy LPA lookup'!$D:$D) -> London Legacy Development Corporation | F684: =IF(ISBLANK('Master Submitted DPDs'!B6),"",'Master Submitted DPDs'!B6) -> 1609 | G684: =IF(ISBLANK('Master Submitted DPDs'!AS6),"","Withdrawn") | H684: =IF(ISBLANK('Master Submitted DPDs'!AS6),"",'Master Submitted DPDs'!AS6) | L684: =IF(ISBLANK('Master Submitted DPDs'!J6),"",'Master Submitted DPDs'!J6) -> 42046 | M684: =L684 -> 42046 | N684: =IF(ISBLANK('Master Submitted DPDs'!M6),IF(ISBLANK('Master Submitted DPDs'!O6),"",'Master Submitted DPDs'!O6),'Master Submitted DPDs'!M6) -> 42047 | O684: =IF(ISBLANK('Master Submitted DPDs'!Q6),"",'Master Submitted DPDs'!Q6) -> 42209 | P684: =IF(ISBLANK('Master Submitted DPDs'!AO6),"",'Master Submitted DPDs'!AO6) -> 42507 | Q684: =IF(ISBLANK('Master Submitted DPDs'!AU6),"",'Master Submitted DPDs'!AU6) -> SOU | R684: =IF(F684="","",IF(AND(H684="",Q684<>"UNS",P684=""),"Open","Closed")) -> Closed | T684: =IF(ISBLANK('Master Submitted DPDs'!G6),"",'Master Submitted DPDs'!G6) -> D
A685: =IF(ISBLANK('Master Submitted DPDs'!#REF!),"","Local Plans") -> Local Plans | B685: =IF(ISBLANK('Master Submitted DPDs'!F7),"",'Master Submitted DPDs'!F7) -> M&W | C685: =IF(ISBLANK('Master Submitted DPDs'!$B7),"","IH") -> IH | D685: =LOOKUP($F685,'fuzzy LPA lookup'!$E:$E,'fuzzy LPA lookup'!$A:$A) -> D1265 | E685: =LOOKUP($F685,'fuzzy LPA lookup'!$E:$E,'fuzzy LPA lookup'!$D:$D) -> Dorset | F685: =IF(ISBLANK('Master Submitted DPDs'!B7),"",'Master Submitted DPDs'!B7) -> 1530 | G685: =IF(ISBLANK('Master Submitted DPDs'!AS7),"","Withdrawn") | H685: =IF(ISBLANK('Master Submitted DPDs'!AS7),"",'Master Submitted DPDs'!AS7) | L685: =IF(ISBLANK('Master Submitted DPDs'!J7),"",'Master Submitted DPDs'!J7) -> 42052 | M685: =L685 -> 42052 | N685: =IF(ISBLANK('Master Submitted DPDs'!M7),IF(ISBLANK('Master Submitted DPDs'!O7),"",'Master Submitted DPDs'!O7),'Master Submitted DPDs'!M7) -> 42052 | O685: =IF(ISBLANK('Master Submitted DPDs'!Q7),"",'Master Submitted DPDs'!Q7) -> 42152 | P685: =IF(ISBLANK('Master Submitted DPDs'!AO7),"",'Master Submitted DPDs'!AO7) -> 42244 | Q685: =IF(ISBLANK('Master Submitted DPDs'!AU7),"",'Master Submitted DPDs'!AU7) -> SOU | R685: =IF(F685="","",IF(AND(H685="",Q685<>"UNS",P685=""),"Open","Closed")) -> Closed | T685: =IF(ISBLANK('Master Submitted DPDs'!G7),"",'Master Submitted DPDs'!G7) -> C
