Workbook
Name AC_gross_in: '[1]Programme Trajectory Input'!$D$101:$K$101
Name AC_net: '[1]Programme Trajectory Input'!$D$105:$K$105
Name Agri_Res_gross_in: '[1]Programme Trajectory Input'!$D$60:$K$60
Name BTR_gross_cum_in: '[1]Programme Trajectory Input'!$D$42
Name Demo_rebuild_PDR_gross_in: '[1]Programme Trajectory Input'!$D$61:$K$61
Name Ebbsfleet_additionality_factor_in: '[1]Programme Trajectory Input'!$C$90
Name Ebbsfleet_net: '[1]Programme Trajectory Input'!$D$91:$K$91
Name GBB_gross_cum_in: '[1]Programme Trajectory Input'!$D$43
Name HD_gross_in: '[1]Programme Trajectory Input'!$D$59:$K$59
Name House_price_growth: '[1]Private Baseline Calculation'!$AB$11
Name HtB_additionality_factor_in: '[1]Programme Trajectory Input'!$C$78
Name HtB_gross_in: '[1]Programme Trajectory Input'!$D$76:$K$76
Name Interbank_rate_prev3_q: '[1]Private Baseline Calculation'!$AB$10
Name Lag: '[1]Private Baseline Calculation'!$AB$18
Name Legacy_additionality_factor_in: '[1]Programme Trajectory Input'!$C$48
Name Legacy_dist_in: '[1]Programme Trajectory Input'!$D$44:$K$44
Name Legacy_gross: '[1]Programme Trajectory Input'!$D$45:$K$45
Name Legacy_net: '[1]Programme Trajectory Input'!$D$50:$K$50
Name LTF_additionality_factor: '[1]Programme Trajectory Input'!$C$34
Name LTF_dist_in: '[1]Programme Trajectory Input'!$D$30:$K$30
Name LTF_gross: '[1]Programme Trajectory Input'!$D$31:$K$31
Name LTF_gross_in: '[1]Programme Trajectory Input'!$D$29
Name LTF_net: '[1]Programme Trajectory Input'!$D$36:$K$36
Name Planning_additonality_factor_in: '[1]Programme Trajectory Input'!$C$65
Name Planning_gross: '[1]Programme Trajectory Input'!$D$63:$K$63
Name Planning_net: '[1]Programme Trajectory Input'!$D$67:$K$67
Name Pro_rata_factor: '[1]Programme Trajectory Input'!$D$18
Name Q1_: '[1]Private Baseline Calculation'!$AB$7
Name Q2_: '[1]Private Baseline Calculation'!$AB$8
Name Q3_: '[1]Private Baseline Calculation'!$AB$9
Name STIF_addiitonality_factor: '[1]Programme Trajectory Input'!$C$21
Name STIF_AF: '[1]Programme Trajectory Input'!$C$21
Name STIF_cs_in: '[1]Programme Trajectory Input'!$D$11:$K$11
Name STIF_fs_in: '[1]Programme Trajectory Input'!$D$12:$K$12
Name STIF_gross: '[1]Programme Trajectory Input'!$D$14:$K$14
Name STIF_gross_cum_total_in: '[1]Programme Trajectory Input'!$D$16
Name STIF_gross_cum_total_update_in: '[1]Programme Trajectory Input'!$D$17
Name STIF_net: '[1]Programme Trajectory Input'!$D$23:$K$23

Sheet LIVE LDS Data
A1: DO NOT EDIT
A2: ONSCODE | B2: Unique VLS code [only to be used where there is more than one plan] | C2: Local Planning Authority | D2: Title of Emerging Development Plan Document | E2: LDF Number | F2: Plan Period Start (YYYY) | G2: Plan Period End (YYYY) | H2: Aligned Plan (Y/N) | I2: Joint Plan (Y/N) | J2: Current Plan Adopted | K2: Previous Plan Adopted | L2: Delay | M2: Reason for delay | N2: Support Given | O2: Early Review? | P2: Emerging Plan Published | Q2: Emerging Plan Submitted | R2: Emerging Found Sound | S2: Emerging Plan found not legally compliant/unsound | T2: Emerging Plan Withdrawn / Work Stopped | U2: Self Review Date | V2: Decision | W2: LIVE Timetable or LIVE Reg 18? | X2: Timetable published? | Y2: Type of Timetable | Z2: IF no LDS or Timetable, has Reg 18 (or later) commenced? | AA2: URL of page including link to LDS | AB2: URL of LDS PDF | AC2: LDS Screenshot link | AD2: Date of LDS or website timetable (MMM-YYYY) | AE2: Scheduled date of first Regulation 18 consultation (as stated in LDS) | AF2: Title of consultation (if applicable) | AG2: Scheduled date of first Regulation 18 consultation (MMM-YYYY) | AH2: Actual Start date of First Regulation 18 Consultation | AI2: Actual End date of First Regulation 18 Consultation | AJ2: URL of First Reg 18 | AK2: Screenshot of First Reg 18 | AL2: Scheduled date of second Regulation 18 consultation (as stated in LDS) | AM2: Title of consultation (if applicable)- | AN2: Scheduled date of second Regulation 18 consultation (MMM-YYYY) | AO2: Actual Start date of Second Regulation 18 Consultation | AP2: Actual End date of Second Regulation 18 Consultation | AQ2: URL of Second Reg 18 | AR2: Screenshot of Second Reg 18 | AS2: Scheduled date of third Regulation 18 consultation (as stated in LDS) | AT2: Title of consultation (if applicable)-2 | AU2: Scheduled date of third Regulation 18 consultation (MMM-YYYY) | AV2: Actual Start date of Third Regulation 18 Consultation | AW2: Actual End date of Third Regulation 18 Consultation | AX2: URL of Third Reg 18 | AY2: Screenshot of Third Reg 18 | AZ2: Scheduled date of fourth Regulation 18 consultation (as stated in LDS) | BA2: Title of consultation (if applicable)-- | BB2: Scheduled date of fourth Regulation 18 consultation (MMM-YYYY) | BC2: Actual Start date of Fourth Regulation 18 Consultation | BD2: Actual End date of Fourth Regulation 18 Consultation | BE2: URL of Fourth Reg 18 | BF2: Screenshot of Fourth Reg 18 | BG2: Scheduled date of publication (as stated in LDS) | BH2: Scheduled date of publication (MMM-YYYY) | BI2: Actual Date of Publication | BJ2: Scheduled date of submission (as stated in LDS) | BK2: Scheduled date of submission (MMM-YYYY) | BL2: Actual Date of submission | BM2: Scheduled date of adoption (as stated in LDS) | BN2: Scheduled date of adoption (MMM-YYYY) | BO2: Actual Date of Adoption | BP2: Source of intel/comments/notes | BQ2: Any further notes - not for summary table | BR2: Emerging Joint Plan Summary Position (if applicable, for summary) | BS2: Date LDS checked (no change) | BT2: Date LDS updated (with changes) | BU2: Date Consultation Timetable checked (no change) | BV2: Date Consultation Timetable updated (with changes) | BW2: Intel updated (if applicable) | BX2: STAGE ** | BY2: Current Delay (months) | BZ2: Monitoring ('Alpha') | CA2: Change detected | CB2: Change omitted | CC2: Change omitted - Notes | CD2: PINS Intel Received? (Y/N)
A3: E07000223 | C3: Adur | D3: Adur Local Plan | E3: 2342 | F3: 2024 | G3: 2039 | H3: N | I3: N | J3: 43083 | L3: YES | U3: 2021 | V3: Decided it is necessary to update the Plan (source: November 2021 newsletter). | W3: =IF(OR(X3="Yes", Y3="Web-page timetable", Z3="YES"), "Yes") -> Yes | X3: Yes | Y3: LDS Document | AA3: https://www.adur-worthing.gov.uk/adur-local-plan-update/#adur-lds | AB3: https://www.adur-worthing.gov.uk/media/Media,98763,smxx.pdf | AD3: 45717 | AE3: Summer 2024 | AF3: Reg 18 consultation | AG3: 45474 | AH3: 45622 | AI3: 46027 | AJ3: https://www.adur-worthing.gov.uk/alp-key-issues-consultation/ | AL3: 46327 | AM3: Reg 18 | AN3: 46327 | BG3: 46600 | BH3: 46600 | BJ3: 46722 | BK3: 46722 | BM3: 46905 | BN3: 46905 | BP3: Draft LDS Mar 2025 | BS3: 45562 | BT3: 45743 | BU3: 45562 | BV3: 45743 | BW3: 45743 | BX3: new plan to be prepared under new system | BZ3: VisualPing | CA3: x
A4: E07000026 | C4: Allerdale (now part of Cumberland) | D4: Allerdale Local Plan Review | J4: 41836 | L4: YES | M4: Nutrient neutrality (March 2022); | W4: =IF(OR(X4="Yes", Y4="Web-page timetable", Z4="YES"), "Yes") -> FALSE | X4: Yes, but refers to something else | Y4: LDS Document | AA4: https://www.allerdale.gov.uk/en/planning-building-control/planning-policy/local-development-scheme/ | AB4: https://www-cloudfront.allerdale.gov.uk/media/filer_public/a8/7d/a87d1a25-6deb-4a2d-bf14-1d77a25a173c/lds_march_2022.pdf | AD4: 44621 | BG4: 45170 | BH4: 45170 | BJ4: 45261 | BK4: 45261 | BM4: TBC | BN4: TBC | BS4: 45061 | BT4: 44659 | BV4: 44796 | BW4: 44796 | BX4: DEFUNCT LPA [new unitary authority to prepare plan] | BZ4: VisualPing
A5: E07000032 | C5: Amber Valley | D5: Amber Valley Borough Local Plan | E5: 2191 | F5: 2022 | G5: 2040 | H5: N | I5: N | J5: none | L5: Yes | M5: Previous emerging plan withdrawn May 2019 DtC - 2023 (with Derby over meeting their unmet need) | P5: 45338 | Q5: 45502 | W5: =IF(OR(X5="Yes", Y5="Web-page timetable", Z5="YES"), "Yes") -> Yes | X5: Yes | Y5: LDS Document | AA5: https://www.ambervalley.gov.uk/planning/planning-policy/local-development-scheme/ | AB5: https://info.ambervalley.gov.uk/docarc/docviewer.aspx?docguid=d8d0717dd04d40f993ce3dfd0c84fb07 | AD5: 45689 | AE5: July - Sep 2021 | AF5: Alternative Spatial Strategy Options | AG5: 44378 | AH5: 44378 | AI5: 44440 | AJ5: https://www.ambervalley.gov.uk/planning/planning-policy/local-plan/alternative-spatial-strategy-options-for-housing-and-economic-growth/ | AL5: July - Aug 2022 | AM5: Preferred Spatial Strategy and draft policies | AN5: 44743 | AO5: 44757 | AP5: 44806 | AQ5: https://www.ambervalley.gov.uk/planning/planning-policy/local-plan/ | BG5: 45292 | BH5: 45292 | BI5: 45338 | BJ5: 45383 | BK5: Apr-2024 | BL5: 45502 | BM5: 46082 | BN5: 46082 | BP5: Feb 2025 LDS | BQ5: March-2024 (was TBC, Sep-2023) pins est. 29/04/24 | BS5: 45960 | BT5: 45743 | BV5: 45743 | BW5: 46027 | BX5: Submitted July 2024 | BZ5: VisualPing
A6: E07000224 | C6: Arun | D6: Arun Local Plan Update 2023 - 2041 | E6: 2328 | F6: 2023 | G6: 2041 | H6: N | I6: N | J6: 43299 | L6: YES | M6: Expected changes to Planning Bill | W6: =IF(OR(X6="Yes", Y6="Web-page timetable", Z6="YES"), "Yes") -> Yes | X6: Yes | Y6: LDS Document | AA6: https://www.arun.gov.uk/local-development-scheme-lds | AB6: https://www.arun.gov.uk/arun-district-council-local-development-scheme | AD6: 45717 | AE6: Spring/Summer 2024 | AF6: Issues and Options | AG6: 45383 | AH6: 45376 | AI6: 45536 | AJ6: https://www.arun.gov.uk/arun-local-plan-update-2023-2041/ | AL6: April - Sept 2026 | AM6: Draft DPD consultation | AN6: 46113 | BG6: April - Sept 2027 | BH6: 46478 | BJ6: 46753 | BK6: 46753 | BM6: Summer 2028 | BN6: 46935 | BP6: LDS Updates - Mar 2025 (draft LDS) | BQ6: consulted on the first document to inform production of the Local Plan update from 25 March until 13 May 2024 | BS6: 45576 | BT6: 45743 | BU6: 45576 | BV6: 45743 | BW6: 45302 | BX6: new plan to be prepared under new system
A7: E07000170 | C7: Ashfield | D7: Local Plan 2023-2040 | E7: 2131 | F7: 2023 | G7: 2040 | H7: N | I7: N | J7: none | L7: YES | M7: change of political control LHN | P7: 45261 | Q7: 45411 | W7: =IF(OR(X7="Yes", Y7="Web-page timetable", Z7="YES"), "Yes") -> Yes | X7: Yes | Y7: LDS Document | AA7: https://www.ashfield.gov.uk/planning-and-building-control/emerging-local-plan/ | AB7: https://www.ashfield.gov.uk/media/fcrpp1b4/local-development-scheme-january-2025.docx | AD7: 45658 | AE7: January/February 2020 | AF7: Draft Plan | AG7: 43831 | AH7: 44473 | AI7: 44516 | AJ7: https://www.ashfield.gov.uk/planning-building-control/local-plan/emerging-local-plan/ | BG7: Nov 2023-Feb 2024 | BH7: 45231 | BI7: 45261 | BJ7: 45413 | BK7: 45413 | BL7: 45411 | BM7: 46203 | BN7: 46174 | BP7: LDS Updates - Mar 2025 | BQ7: Ashfield had a change of policital control in 2018 (to independents) and subsequently decided to withdraw their plan from examination in September 2018. Ashfield then started work on a new Local Plan. | BS7: 45960 | BT7: 45743 | BU7: 44825 | BV7: 45743 | BW7: 45868 | BX7: Submitted April 2024 [plan paused] | BZ7: Published - Dec 2023 Visualping
A8: E07000105 | C8: Ashford | D8: Ashford Local Plan 2042 | E8: 2354 | F8: 2024 | G8: 2042 | H8: N | I8: N | J8: 43517 | L8: YES | M8: Nutrient neutrality (since 2018) | W8: =IF(OR(X8="Yes", Y8="Web-page timetable", Z8="YES"), "Yes") -> Yes | X8: Yes | Y8: LDS Document | AA8: https://www.ashford.gov.uk/planning-and-development/our-planning-policies/planning-policy-consultations-current-historic/local-development-scheme/ | AB8: https://www.ashford.gov.uk/media/zegd5h5p/lds-2024-1-use.pdf | AD8: 45474 | AE8: Qtr 2 2025 | AF8: Reg 18 consultation | AG8: 45748 | AH8: 45887 | AI8: 45943 | AJ8: https://haveyoursay.ashford.gov.uk/draft-lp42-consultation | BG8: Q1 2026 | BH8: 46054 | BJ8: Q3 2026 | BK8: 46266 | BM8: Q3 2027 | BN8: 46478 | BP8: LDS Updates - Mar 2025 | BS8: 46024 | BT8: 45743 | BU8: 45856 | BV8: 45918 | BW8: 45743 | BX8: Reg 18 completed | BZ8: VisualPing
A9: E07000004 | C9: Aylesbury Vale (defunct) | D9: The Vale of Aylesbury Local Plan (VALP) | J9: 44454 | K9: none [Sep 2021 adopted plan is first post-2004 Act Plan] | P9: 43041 | Q9: 43159 | R9: 44427 | W9: =IF(OR(X9="Yes", Y9="Web-page timetable", Z9="YES"), "Yes") -> Yes | X9: Yes | Y9: LDS Document | AA9: https://www.aylesburyvaledc.gov.uk/section/vale-aylesbury-local-plan-valp-2013-2033 | AB9: https://www.aylesburyvaledc.gov.uk/sites/default/files/page_downloads/2018%20%28Jan%29%20LDS%20FINAL_0.pdf | AC9: https://teams.microsoft.com/_#/png/viewer/teams/https:~2F~2Fmhclg.sharepoint.com~2Fsites~2FDevelopmentPlans~2FShared%2520Documents~2FData%2520and%2520Analysis~2FPlanning%2520Data%2520Unit~2FData%2520Project~2FShort-term%2520Solution~2FLDS%2520Approach~2FLDS%2520screen%2520captures~2FAYL18%2520-%2520Aylesbury%2520Vale%2520LDS%25202018.PNG?threadId=19:02cfc1d922c64c5584e5731b4a607ece@thread.skype&fileId=4A363F8A-D4AC-4A42-99AE-01F460EE805E&ctx=files&viewerAction=view | AD9: 43101 | AE9: October-December 2015 | AG9: 42309 | AL9: July to September 2016 | AN9: 42583 | BG9: November/December 2017 | BH9: 43040 | BI9: =P9 -> 43041 | BJ9: 43132 | BK9: 43132 | BL9: =Q9 -> 43159 | BM9: 43466 | BN9: 43466 | BO9: 44440 | BS9: 43676 | BW9: 44461 | BX9: DEFUNCT LPA [new unitary authority to prepare plan]
A10: E07000200 | C10: Babergh | D10: Babergh & Mid Suffolk Joint Local Plan | E10: TBA | H10: N | I10: Y | J10: 45251 | K10: 41695 | W10: =IF(OR(X10="Yes", Y10="Web-page timetable", Z10="YES"), "Yes") -> Yes | X10: Yes | Y10: LDS Document | AA10: https://www.babergh.gov.uk/joint-local-plan | AB10: https://www.babergh.gov.uk/documents/d/asset-library-54706/babergh-and-mid-suffolk-joint-local-development-scheme-2025-2029 | AD10: 45717 | AE10: Aug 2026 - Mar 2027 | AF10: First Public Consultation | AG10: 46235 | BG10: Jan - June 2028 | BH10: 46753 | BJ10: 46905 | BK10: 46905 | BM10: 47209 | BN10: 47209 | BP10: LDS Updates - Mar 2025 (joint Feb 2025 LDS). Website (02/10/2025) | BS10: 45960 | BT10: 45743 | BV10: 45743 | BW10: 45932 | BX10: new plan to be prepared under new system | BZ10: Babergh adopted 21 Nov 2023 | CD10: Yes
A11: E09000002 | C11: Barking & Dagenham | D11: New Local Plan | H11: N | I11: N | J11: 45553 | K11: 40380 | L11: YES | M11: OTHER | W11: =IF(OR(X11="Yes", Y11="Web-page timetable", Z11="YES"), "Yes") -> Yes | X11: Yes | Y11: LDS Document | AA11: https://www.lbbd.gov.uk/planning-building-control-and-local-land-charges/planning-guidance-and-policies/local-plan | AB11: https://www.lbbd.gov.uk/sites/default/files/2025-02/LDS%20February%202025%20Update.pdf | AD11: 45689 | AE11: 2028 | AF11: Reg 18 equivalent | AG11: 2028 | BG11: 46935 | BH11: 46935 | BJ11: 47119 | BK11: 47119 | BM11: 47453 | BN11: 47453 | BP11: LDS Updates - Mar 2025 | BS11: 45961 | BT11: 45743 | BU11: 44267 | BV11: 45743 | BW11: 45700 | BX11: new plan to be prepared under new system | BZ11: Submitted Dec 2021
A12: E09000003 | C12: Barnet | D12: New Local Plan for Barnet | H12: N | I12: N | J12: 45720 | K12: 41163 | W12: =IF(OR(X12="Yes", Y12="Web-page timetable", Z12="YES"), "Yes") -> Yes | X12: Yes | Y12: LDS Document | AA12: https://www.barnet.gov.uk/planning-and-building/planning-policies/local-plan-review | AB12: https://www.barnet.gov.uk/sites/default/files/appendix_g_-_local_development_scheme.pdf | AC12: https://mhclg.sharepoint.com/sites/DevelopmentPlans/Shared%20Documents/Data%20and%20Analysis/Planning%20Data%20Unit/LDS%20&%20Reg%2018%20Monitoring/LDS%20Screenshots/BAR20%20-%20Barnet%20LDS%20Jan%202020.PNG | AD12: 45689 | AE12: 46174 | AF12: Reg 18 equivalent | AG12: 46174 | AL12: 46388 | AM12: Reg 18 equivalent | AN12: 46388 | BG12: 46569 | BH12: 46569 | BJ12: 46874 | BK12: 46874 | BM12: 47058 | BN12: 47058 | BP12: LDS (Feb 2025) | BS12: 45961 | BT12: 45744 | BU12: 44463 | BV12: 45744 | BW12: 45744 | BX12: new plan to be prepared under new system | BZ12: Submitted Nov 2021
A13: E08000016 | C13: Barnsley | D13: new system | E13: n/a | J13: 43468 | U13: 44889 | V13: No need to update local plan. Further review in 2027 | W13: =IF(OR(X13="Yes", Y13="Web-page timetable", Z13="YES"), "Yes") -> FALSE | X13: No | Y13: None | BP13: LPA's website | BQ13: The Local Plan review was endorsed at a meeting of Full Council on 24 November 2022. The review concluded that the Local plan remains fit for purpose and is adequately delivering its objectives. This means no updates to the Local Plan, in whole or in part, are to be carried out ahead of a further review. A further review will take place in 2027 or earlier if circumstances, including fundamental changes to the Local Plan system, require it. | BS13: 23/08/2023 [none found] | BW13: 44648 | BX13: new plan to be prepared under new system
A14: E07000027 | C14: Barrow-in-Furness (unitarised in 2023, now Westmorland and Furness) | D14: Barrow Borough Council Local Plan | J14: 43620 | W14: =IF(OR(X14="Yes", Y14="Web-page timetable", Z14="YES"), "Yes") -> FALSE | X14: Yes, but TT refers to adopted Plan | Y14: LDS Document | AA14: https://www.barrowbc.gov.uk/residents/planning/planning-policy/examination-of-local-plan/examination-library/supporting-documents/ | AB14: https://www.barrowbc.gov.uk/residents/planning/planning-policy/examination-of-local-plan/examination-library/supporting-documents/?entryid1=5956 | AC14: https://teams.microsoft.com/_#/png/viewer/teams/https:~2F~2Fmhclg.sharepoint.com~2Fsites~2FDevelopmentPlans~2FShared%20Documents~2FData%20and%20Analysis~2FPlanning%20Data%20Unit~2FData%20Project~2FShort-term%20Solution~2FLDS%20Approach~2FLDS%20screen%20captures~2FBAR16%20-%20Barrow-in-Furness%20LDS%202016.PNG?threadId=19:02cfc1d922c64c5584e5731b4a607ece@thread.skype&baseUrl=https:~2F~2Fmhclg.sharepoint.com~2Fsites~2FDevelopmentPlans&fileId=5FA8388F-9974-45E1-BC07-1BC0787AC89F&ctx=files&viewerAction=view | AD14: 43497 | BS14: 45013 | BU14: 45013 | BX14: DEFUNCT LPA [new unitary authority to prepare plan]
A15: E07000066 | C15: Basildon | D15: New Local Plan (previous emerging plan withdrawn from examination) | E15: 2299 | F15: 2023 | G15: 2043 | H15: N | I15: N | J15: none | L15: Yes | M15: Previous emerging plan withdrawn from examination | W15: =IF(OR(X15="Yes", Y15="Web-page timetable", Z15="YES"), "Yes") -> Yes | X15: Yes | Y15: LDS Document | AA15: https://www.basildon.gov.uk/article/2012/Timetable-and-Consultation-Standards | AB15: https://www.basildon.gov.uk/media/12610/Basildon-Borough-Council-Local-Development-Scheme-2025-2026/pdf/Basildon_Borough_Council_Local_Development_Scheme_2025-2026.pdf?m=1761645190953 | AD15: 45931 | AE15: Q2 2023 | AF15: Issues and Options Consultation | AG15: 45047 | AH15: 45104 | AI15: 45174 | AJ15: https://www.basildon.gov.uk/article/9107/Local-Plan-Latest-news-and-updates | AK15: https://basildonlocalplan.commonplace.is/timeline | AL15: Winter 2024 (Q1) | AM15: First Draft Local Plan Consultation (Reg 18) | AN15: 45658 | AO15: 45597 | AP15: 45658 | AQ15: https://www.basildon.gov.uk/article/9107/Local-Plan-Latest-news-and-updates | AS15: 45689 | AT15: Second Focused Draft Local Plan consultation | AU15: 45748 | AV15: 45719 | AW15: 45761 | AX15: https://basildonlocalplan.commonplace.is/timeline | AZ15: Nov 2025 - Jan 2026 | BA15: Third Draft Plan consultation | BB15: 45962 | BC15: 45989 | BD15: 46038 | BE15: https://www.basildon.gov.uk/article/9107/Local-Plan-Latest-news-and-updates | BG15: Q1 2026 winter | BH15: 46023 | BJ15: Q2 2026 Spring | BK15: 46113 | BM15: Q4 2026 autumn | BN15: 46296 | BP15: Oct 2025 LDS & LPA website (Dec 2025) | BS15: 46024 | BT15: 45960 | BU15: 45121 | BV15: 45996 | BW15: 45996 | BX15: Reg 18 ongoing | BZ15: VisualPing
A16: E07000084 | C16: Basingstoke and Deane | D16: Local Plan | E16: 2327 | F16: 2021 | G16: 2040 | H16: N | I16: N | J16: 42516 | L16: YES | M16: Nutrient neutrality (since 2018) | W16: =IF(OR(X16="Yes", Y16="Web-page timetable", Z16="YES"), "Yes") -> Yes | X16: Yes | Y16: Web-page timetable | AA16: https://www.basingstoke.gov.uk/LDS | AB16: https://www.basingstoke.gov.uk/LDS | AD16: 45689 | AE16: Winter 2023/24 | AF16: Draft Plan (Reg 18) | AG16: 45292 | AH16: 45313 | AI16: 45355 | AJ16: https://www.basingstoke.gov.uk/LPU-reg18-consultation | AL16: Autumn/Winter 2025 | AM16: Additional consultation on draft plan | AN16: 45931 | BG16: Summer 2026 | BH16: 46204 | BJ16: Winter 2026 | BK16: 46357 | BM16: Winter 2027 | BN16: 46753 | BP16: LDS (Feb 2025) | BR16: 45589 | BS16: 46297 | BT16: 45743 | BU16: 45298 | BV16: 45743 | BW16: 45744 | BX16: Reg 18 ongoing | BZ16: VisualPing
A17: E07000171 | C17: Bassetlaw | D17: Bassetlaw Local Plan 2028-2043 | E17: TBC | F17: 2028 | G17: 2043 | H17: N | I17: N | J17: 45441 | K17: 40899 | W17: =IF(OR(X17="Yes", Y17="Web-page timetable", Z17="YES"), "Yes") -> Yes | X17: Yes | Y17: LDS Document | AA17: https://www.bassetlaw.gov.uk/planning-and-building/planning-services/planning-policy/local-development-scheme/ | AB17: https://www.bassetlaw.gov.uk/media/zeffmlis/local-development-scheme-2025.pdf | AD17: 45717 | BG17: TBC | BH17: TBC | BJ17: 46997 | BK17: 46997 | BM17: April - May 2029 | BN17: 47209 | BP17: LDS (March 2025) | BQ17: Draft Bassetlaw Plan (Nov 2020) consulted on Nov 2020 - Jan 2021. A further Reg 18 consultation (Draft Bassetlaw Local Plan Focussed Consultation) closed 21 July 2021, but not recorded on our timeline here. | BS17: 45071 | BT17: 45744 | BV17: 45744 | BW17: 45744 | BX17: new plan to be prepared under new system | BZ17: FS 21 Feb 2024
B18: E06000022-03 | C18: Bath & North East Somerset | D18: Bath and North East Somerset Local Plan (Core Strategy and Placemaking Plan incorporating the Local Plan Partial Update) [not strategic in terms of housing requirement] | E18: 2103 | F18: 2011 | G18: 2029 | H18: N | I18: N | J18: 10 July 2014 (as amended by partial update on 19 Jan 2023) | P18: 44435 | Q18: 44547 | R18: 44908 | W18: =IF(OR(X18="Yes", Y18="Web-page timetable", Z18="YES"), "Yes") -> Yes | X18: Yes | Y18: LDS Document | AA18: https://beta.bathnes.gov.uk/planning-consultation-local-plan-partial-update-and-statement-community-involvement | AB18: https://beta.bathnes.gov.uk/sites/default/files/2021-08/LDS%20July%202021%20Final%20-%20accessible.pdf | AD18: 2022 | AE18: April - June 2020 | AF18: Planning consultation: Local Plan partial update and Statement of Community Involvement | AG18: 43922 | AH18: 43927 | AI18: 43983 | AJ18: https://beta.bathnes.gov.uk/sites/default/files/2020-04/LP%20Commencement%20April%202020v5%20%28FINAL%29.pdf | AL18: Nov/Dec 2020 | AM18: Options Consultation | AN18: 44136 | AO18: 44203 | AP18: 44245 | AQ18: https://beta.bathnes.gov.uk/local-plan-partial-update-options-consultation | BM18: 44927 | BN18: 44927 | BO18: 44927 | BR18: Statutory consultation on draft plan scheduled for Spring 2022 but missed. Work halted due to lack of agreement by South Gloucestershire (who want to commence work on their own plan). | BS18: 44736 | BT18: 44629 | BU18: 44656 | BV18: 44629 | BW18: 44629 | BX18: partial update adopted Jan-2023 | BZ18: Adopted 19 Jan 2023
B19: E06000022-02 | C19: Bath & North East Somerset | D19: WECA Spatial Development Strategy (SDS) | F19: 2022 | G19: 2042 | H19: N | I19: SDS | J19: 10 July 2014 (as amended by partial update on 19 Jan 2023) | L19: YES | M19: lack of agreement | W19: =IF(OR(X19="Yes", Y19="Web-page timetable", Z19="YES"), "Yes") -> Yes | X19: Yes | Y19: LDS Document | AA19: https://www.westofengland-ca.gov.uk/what-we-do/planning-housing/spatial-development-strategy/ | AB19: https://beta.bathnes.gov.uk/sites/default/files/2021-08/LDS%20July%202021%20Final%20-%20accessible.pdf | AD19: 2021 | AE19: Second Half of 2021 | AF19: Draft SDS Public consultation | AG19: 44378 | BG19: Spring 2022 | BH19: 44652 | BJ19: Spring 2023 | BK19: 45017 | BM19: TBC | BN19: TBC | BR19: Statutory consultation on draft plan scheduled for Spring 2022 but missed. Work halted due to lack of agreement by South Gloucestershire (who want to progress work on their own plan). | BS19: 44628 | BU19: 44628 | BW19: 44740 | BX19: work stopped | BZ19: VisualPing
A20: E06000022 | C20: Bath & North East Somerset | D20: Bath and North East Somerset Council New Local Plan (2022-2042) | E20: 2290 | F20: 2022 | G20: 2042 | H20: N | I20: N | J20: 10 July 2014 (as amended by partial update on 19 Jan 2023) | W20: Yes | X20: Yes | Y20: LDS Document | AA20: https://beta.bathnes.gov.uk/policy-and-documents-library/local-development-scheme | AB20: https://www.bathnes.gov.uk/policy-and-documents-library/local-development-scheme | AD20: 45748 | AE20: 44835 | AF20: Options Consultation | AG20: 44835 | AH20: 44838 | AI20: 44880 | AJ20: https://beta.bathnes.gov.uk/local-plan-launch-document-consultation | AL20: Oct - Dec 2023 | AM20: Options | AN20: 45200 | AO20: 45334 | AP20: 45390 | AQ20: https://beta.bathnes.gov.uk/local-plan-2022-2042-development-timeline | AS20: Aug - Sep 2025 | AT20: Options | AU20: 45870 | AV20: 45931 | AW20: 45962 | AX20: https://bathnesplaces.co.uk/localplan/ | BG20: May - July 2026 | BH20: 46143 | BJ20: 46296 | BK20: 46296 | BM20: Sept/Oct 2027 | BN20: 46631 | BP20: April 2025 LDS revision | BS20: 46024 | BT20: 46031 | BV20: 46031 | BW20: 46031 | BX20: Reg 18 completed | BZ20: VisualPing
A21: E06000055 | C21: Bedford | D21: Local Plan 2040 | E21: 2183 | F21: 2020 | G21: 2040 | H21: N | I21: N | J21: 43845 | O21: YES | P21: 44727 | Q21: 44938 | T21: 45938 | W21: =IF(OR(X21="Yes", Y21="Web-page timetable", Z21="YES"), "Yes") -> Yes | X21: Yes | Y21: LDS Document | AA21: https://www.bedford.gov.uk/planning-and-building-control/planning-policy/local-development-scheme | AB21: https://www.bedford.gov.uk/media/4027/download?inline | AD21: 44562 | AE21: July - Sept 2020 | AF21: Issues and Options | AG21: 44026 | AH21: 44013 | AI21: 44088 | AJ21: https://www.bedford.gov.uk/planning-and-building/planning-policy-its-purpose/local-plan-review/ | AL21: July - Sept 2021 | AM21: Draft Plan Consultation | AN21: 44378 | AO21: 44391 | AP21: 44443 | AQ21: https://www.bedford.gov.uk/planning-and-building/planning-policy-its-purpose/local-plan-review/ | BG21: May - June 2022 | BH21: 44682 | BI21: 44727 | BJ21: 44927 | BK21: 44927 | BL21: 44938 | BM21: 45261 | BN21: 45261 | BS21: 45961 | BT21: 44461 | BV21: 44960 | BX21: WITHDRAWN 8 Oct 2025 | BZ21: early review Submitted Jan 2023
A22: E09000004 | C22: Bexley | D22: Bexley Local Plan | E22: TBA | H22: N | I22: N | J22: 45042 | K22: 40961 | U22: 2017 | V22: Will update Plan | W22: =IF(OR(X22="Yes", Y22="Web-page timetable", Z22="YES"), "Yes") -> Yes | X22: Yes | Y22: LDS Document | AB22: https://www.bexley.gov.uk/sites/default/files/2025-03/bexley-local-development-scheme-march-2025.pdf | AD22: 45717 | AE22: 47058 | AF22: Reg 18 equivalent | AG22: 47058 | BG22: 47300 | BH22: 47300 | BJ22: 47543 | BK22: 47543 | BM22: 47757 | BN22: 47757 | BP22: March 2025 LDS | BS22: 45888 | BT22: 44320 | BU22: 45888 | BV22: 45744 | BW22: 45744 | BX22: new plan to be prepared under new system | BZ22: Adopted 26 April 2023
A23: E08000025 | C23: Birmingham | D23: Birmingham Local Plan 2042 | E23: 2300 | F23: 2020 | G23: 2042 | H23: N | I23: N | J23: 42745 | L23: YES | U23: 43983 | V23: need to update local plan | W23: =IF(OR(X23="Yes", Y23="Web-page timetable", Z23="YES"), "Yes") -> Yes | X23: Yes | Y23: LDS Document | AA23: https://www.birmingham.gov.uk/downloads/file/845/local_development_scheme_for_birmingham | AB23: https://www.birmingham.gov.uk/download/downloads/id/845/local_development_scheme_for_birmingham.pdf | AD23: 45689 | AE23: Oct - Nov 2022 | AF23: Issues & Options | AG23: 44835 | AH23: 44858 | AI23: 44900 | AJ23: https://www.birmingham.gov.uk/info/20008/planning_and_development/2477/new_local_plan_for_birmingham#:~:text=We%20are%20working%20on%20a,Local%20Plan%20has%20now%20concluded. | AL23: June-July 2024 | AM23: Preferred Options | AN23: 45444 | AO23: 45474 | AP23: 45505 | AS23: Nov/Dec 2025 | AT23: Further Preferred Options | AU23: 45992 | BG23: June/July 2026 | BH23: 46204 | BJ23: 46296 | BK23: 46296 | BM23: 46631 | BN23: 46631 | BP23: Jan/Feb 2025 LDS | BS23: 46024 | BT23: 45686 | BU23: 45960 | BV23: 45686 | BX23: Reg 18 ongoing | BZ23: VisualPing
A24: E07000129 | C24: Blaby | D24: Blaby District New Local Plan | E24: 2112 | F24: 2022 | G24: 2042 | H24: N | I24: N | J24: 41326 | L24: YES | W24: =IF(OR(X24="Yes", Y24="Web-page timetable", Z24="YES"), "Yes") -> Yes | X24: Yes | Y24: LDS Document | AA24: https://www.blaby.gov.uk/planning-and-building/local-plan/about-the-local-plan/ | AB24: https://www.blaby.gov.uk/media/i0of4qyl/blaby-district-local-plan-local-development-scheme-2025.pdf | AD24: 45717 | AE24: July/August 2019 | AF24: Issues and Options | AG24: 43647 | AH24: 43647 | AI24: 43738 | AJ24: https://www.blaby.gov.uk/planning-and-building/local-plan/new-local-plan/ | AK24: https://mhclg.sharepoint.com/sites/DevelopmentPlans/Shared%20Documents/Data%20and%20Analysis/Planning%20Data%20Unit/Reg%2018%20monitoring/Screenshots/Blaby%20Issues%20&%20Options%20June%202019.PNG | AL24: Jan/Feb 2021 | AM24: Draft Plan | AN24: 44197 | AO24: 44197 | AP24: 44256 | AQ24: https://www.blaby.gov.uk/planning-and-building/local-plan/new-local-plan/ | BG24: 46113 | BH24: 46113 | BJ24: TBC (was Dec 2025) | BK24: TBC | BM24: TBC (was Dec 2026) | BN24: TBC | BP24: March 2025 LDS & update from website (Jan 2026) | BS24: 46024 | BT24: 45763 | BU24: 45559 | BV24: 46024 | BW24: 45635 | BX24: Reg 18 completed | BZ24: Email Alert; VisualPing
A25: E06000008 | C25: Blackburn with Darwen | D25: Blackburn with Darwen Local Plan (single plan) | E25: 2104 | F25: 2021 | G25: 2037 | H25: N | I25: N | J25: 45316 | K25: 40570 | L25: YES | M25: Covid-19 | P25: 44596 | Q25: 44778 | R25: 45271 | W25: =IF(OR(X25="Yes", Y25="Web-page timetable", Z25="YES"), "Yes") -> FALSE | X25: Yes, but TT refers to adopted Plan | Y25: LDS Document | AA25: https://www.blackburn.gov.uk/planning/planning-policies-strategies-and-guides/local-development-scheme | AB25: https://democracy.blackburn.gov.uk/documents/s21585/Blackburn%20Local%20Development%20Scheme%202023%20final.pdf | AD25: 45170 | AE25: Feb - April 2019 | AF25: Issues & Options | AG25: 43525 | AH25: 43507 | AI25: 43556 | AJ25: https://www.blackburn.gov.uk/planning/planning-policies-strategies-and-guides/local-plan-review | AK25: https://mhclg.sharepoint.com/:i:/s/DevelopmentPlans/EcFCRibQgYdAkXUZhugunmMBb931QXQ7c-Dl0SiQz2Plkw?e=lWQ2RK | AL25: 44075 | AM25: Draft Local Plan Consultation (Reg 18) | AN25: 44075 | AO25: 44204 | AP25: 44246 | AQ25: http://blackburn-darwen.org.uk/wp-content/uploads/UA-Consultation-Draft-Local-Plan-1.pdf | BG25: Jan - Feb 2022 | BH25: 44562 | BI25: 44596 | BJ25: June - July 2022 | BK25: 44713 | BL25: 44778 | BM25: Summer 2023 | BN25: 45108 | BO25: 45316 | BP25: PINS updates | BS25: 45950 | BT25: 44428 | BU25: 44645 | BV25: 44428 | BX25: no work on an emerging plan [adopted Jan-2024] | BZ25: Adopted Jan 2024
A26: E06000009 | C26: Blackpool | D26: New Local Plan to 2042 | E26: 2301 | F26: 2023 | G26: 2042 | H26: N | I26: N | J26: 42389 | W26: =IF(OR(X26="Yes", Y26="Web-page timetable", Z26="YES"), "Yes") -> Yes | X26: Yes | Y26: LDS Document | AA26: https://democracy.blackpool.gov.uk/documents/s98308/PH29%20Local%20Development%20Scheme.pdf | AB26: https://democracy.blackpool.gov.uk/documents/s98308/PH29%20Local%20Development%20Scheme.pdf | AD26: 45689 | AE26: 46388 | AF26: Reg 18 equivalent | AG26: 46388 | BG26: 47209 | BH26: 47209 | BJ26: 47515 | BK26: 47515 | BM26: 47880 | BN26: 47880 | BP26: Jan 2025 LDS | BQ26: Blackpool have now reviewed the Core Strategy policies: full review of Plan required. July 2022 LDS provides timetable: Reg 18: Sept/Oct 2023; Reg 19: Sept/Oct 2024; Submission: Dec 2024; Adoption: December 2025 | BS26: 45961 | BT26: 45763 | BU26: 45594 | BV26: 44855 | BW26: 45594 | BX26: new plan to be prepared under new system | BZ26: VisualPing
A27: E07000033 | C27: Bolsover | D27: Bolsover Local Plan | H27: N | I27: N | J27: 43894 | W27: =IF(OR(X27="Yes", Y27="Web-page timetable", Z27="YES"), "Yes") -> Yes | X27: Yes | Y27: LDS Document | AA27: https://www.bolsover.gov.uk/services/p/planning-policy/local-development-scheme | AB27: https://www.bolsover.gov.uk/component/edocman/15178-local-development-scheme-no-8/download?Itemid=0 | AD27: 45748 | AE27: 46661 | AF27: Reg 18 equivalent | AG27: 46661 | BG27: 47027 | BH27: 47027 | BJ27: 47150 | BK27: 47150 | BM27: 47453 | BN27: 47453 | BP27: April 2025 LDS | BS27: 45317 | BT27: 45961 | BU27: 45961 | BV27: 45686 | BW27: 31/010/2025 | BX27: new plan to be prepared under new system
A28: E08000001 | C28: Bolton | D28: Places for Everyone (PFE) | E28: 2175 | F28: 2022 | G28: 2039 | H28: N | I28: Y | J28: 45372 | K28: 40604 | P28: 44417 | Q28: 44606 | R28: 45336 | W28: =IF(OR(X28="Yes", Y28="Web-page timetable", Z28="YES"), "Yes") -> Yes | X28: Yes | Y28: Web-page timetable | AA28: https://www.greatermanchester-ca.gov.uk/what-we-do/planning-and-housing/places-for-everyone/timeline/ | AD28: 2023 | BI28: 44417 | BJ28: early 2022 | BK28: 44562 | BL28: 44606 | BO28: 45372 | BR28: Plan Submitted 14 February 2022. Hearings likely to commence October 2022. | BV28: 44440 | BW28: 45279 | BX28: Adopted March 2024 | BZ28: FS 14 Feb 2024
B29: E08000001-01 | C29: Bolton | D29: Bolton Local Plan (non strategic) | W29: =IF(OR(X29="Yes", Y29="Web-page timetable", Z29="YES"), "Yes") -> Yes | X29: Yes | Y29: Web-page timetable | AB29: https://www.bolton.gov.uk/downloads/file/7443/local-plan-direction-of-travel-consultation-document-pdf- | AD29: 45931 | AE29: Spring 2025 | AF29: Issues and Options | AG29: 45748 | AH29: 45890 | AI29: 45902 | AJ29: https://www.bolton.gov.uk/planning-policy-strategy/local-plan/2 | AL29: Autumn 2025 | AM29: Direction of Travel (2nd Reg 18) | AN29: 45931 | AO29: 45988 | AP29: 46044 | AQ29: https://www.bolton.gov.uk/downloads/file/7443/local-plan-direction-of-travel-consultation-document-pdf- | BG29: Summer 2026 | BH29: 46204 | BJ29: Winter 2026 | BK29: 46357 | BM29: 2027 | BN29: 2027 | BP29: Direction of Travel consultation document Oct 2025 | BS29: 46034 | BU29: 46034 | BW29: 46034 | BX29: Reg 18 ongoing
A30: E07000136 | C30: Boston | D30: South East Lincolnshire Local Plan Review | E30: n/a | J30: 43532 | U30: 45474 | V30: That based on the review that has taken place, the Joint Committee conclude that there is no requirement to update the Local Plan at this time | W30: =IF(OR(X30="Yes", Y30="Web-page timetable", Z30="YES"), "Yes") -> FALSE | X30: Yes, but TT refers to adopted Plan | Y30: LDS Document | AA30: http://www.southeastlincslocalplan.org/documents/ | AB30: http://www.southeastlincslocalplan.org/wp-content/uploads/2017/06/Local-Development-Scheme-June-2017.pdf | AD30: 42887 | BS30: 45933 | BX30: self-reviewed new plan to be submitted under new system
A31: E06000028 | C31: Bournemouth (defunct - now part of Bournemouth, Christchurch & Poole) | J31: 41212 | W31: =IF(OR(X31="Yes", Y31="Web-page timetable", Z31="YES"), "Yes") -> FALSE | BX31: DEFUNCT LPA [new unitary authority to prepare plan]
A32: E06000058 | C32: Bournemouth, Christchurch and Poole ("BCP") | D32: BCP Plan | J32: new lpa | Y32: LDS Document | AA32: https://www.bcpcouncil.gov.uk/planning-and-building-control/planning-policy/bcp-local-plan-and-community-infrastructure-levy-cil/local-development-scheme | AB32: https://www.bcpcouncil.gov.uk/Assets/Planning-and-building-control/Local-plan-and-cil/Local-Development-Scheme.pdf | AD32: 45778 | AE32: Aug - Oct 2026 | AF32: Reg 18 Equivalent [consultation on options] | AG32: 46235 | BG32: Sep - Nov 2027 | BH32: 46631 | BJ32: 46813 | BK32: 46813 | BM32: 47027 | BN32: 47027 | BP32: LPA e-mail (27 Aug 2025) | BS32: 45932 | BT32: 45834 | BU32: 45945 | BV32: 45834 | BX32: new plan to be prepared under new system
B33: E06000058-01 | C33: Bournemouth, Christchurch and Poole ("BCP") | D33: BCP Plan | E33: 2143 | F33: 2023 | G33: 2038 | H33: N | I33: N | J33: new LPA | L33: YES | M33: Nutrient neutrality (since 2018) | P33: 45371 | Q33: 45470 | S33: 45719 | T33: 45811 | W33: =IF(OR(X33="Yes", Y33="Web-page timetable", Z33="YES"), "Yes") -> Yes | X33: Yes | Y33: LDS Document | AA33: https://www.bcpcouncil.gov.uk/planning-and-building-control/planning-policy/bcp-local-plan/local-development-scheme | AB33: https://www.bcpcouncil.gov.uk/documents/planning-and-building-control/Local-Development-Scheme-Feb-2024.pdf | AD33: 45292 | AE33: Oct/Nov 2019 | AF33: Issues and Call for Sites Consultation | AG33: 43739 | AH33: 43745 | AI33: 43787 | AJ33: https://www.bcpcouncil.gov.uk/Council-and-Democratic/Consultation-And-Research/Consultations/BCP-Council-Local-Plan.aspx | AL33: Sep/Oct 2020 | AM33: Issues & Options | AN33: 44075 | AO33: 44571 | AP33: 44645 | AQ33: https://haveyoursay.bcpcouncil.gov.uk/localplan | BG33: 45352 | BH33: 45352 | BI33: 45371 | BJ33: 45444 | BK33: 45444 | BL33: 45470 | BM33: Summer 2025 | BN33: 45839 | BP33: LDS - Feb 2024 | BS33: 45420 | BT33: 45377 | BU33: 45441 | BV33: 45475 | BW33: 45763 | BX33: Submitted June 2024, failed DtC 2025; withdrawn 3 June 2025 | BZ33: VisualPing; Published June 2024
A34: E06000036 | C34: Bracknell Forest | D34: Bracknell Forest Local Plan | E34: TBA | H34: N | I34: N | J34: 45370 | K34: 39485 | L34: YES | M34: Covid-19 | W34: =IF(OR(X34="Yes", Y34="Web-page timetable", Z34="YES"), "Yes") -> Yes | X34: Yes | Y34: LDS Document | AA34: https://www.bracknell-forest.gov.uk/planning-and-building-control/planning/planning-policy/about-planning-policy | AB34: https://www.bracknell-forest.gov.uk/sites/default/files/2025-03/local-development-scheme-march-2025.pdf | AD34: 45717 | AE34: Winter/Spring 2028 | AF34: Visioning and strategy development - public consultation | AG34: 46844 | BG34: Spring 2029 | BH34: 47209 | BJ34: Autumn 2029 | BK34: 47392 | BM34: Spring 2030 | BN34: 47574 | BP34: March 2025 LDS | BT34: 45888 | BU34: 44309 | BV34: 45888 | BW34: 45888 | BX34: new plan to be prepared under new system | BZ34: Adopted 19 March 2024
A35: E08000032 | C35: Bradford | D35: Bradford District Local Plan | E35: 2208 | F35: 2020 | G35: 2038 | H35: N | I35: N | J35: 42934 | L35: YES | M35: LHN and White Paper | W35: =IF(OR(X35="Yes", Y35="Web-page timetable", Z35="YES"), "Yes") -> Yes | X35: Yes | Y35: LDS Document | AA35: https://www.bradford.gov.uk/planning-and-building-control/planning-policy/local-development-scheme/ | AB35: https://www.bradford.gov.uk/media/dmidr35l/local-development-scheme-2025-2028.pdf | AD35: 45931 | AE35: 43405 | AF35: Issues & Options (Core Strategy Partial Review) | AG35: 43405 | AH35: 43476 | AI35: 43518 | AJ35: https://www.bradford.gov.uk/planning-and-building-control/planning-policy/core-strategy-dpd/?Folder=Core+Strategy+Partial+Review | AK35: https://mhclg.sharepoint.com/sites/DevelopmentPlans/Shared%20Documents/Data%20and%20Analysis/Planning%20Data%20Unit/Reg%2018%20monitoring/Screenshots/Bradford%20Jan-Feb%202019%20FIRST.PNG | AL35: 43586 | AM35: Preferred Options (Core Strategy Partial Review) | AN35: 43586 | AO35: 43676 | AP35: 43732 | AQ35: https://www.bradford.gov.uk/planning-and-building-control/planning-policy/core-strategy-dpd/?Folder=Core%20Strategy%20Partial%20Review\Preferred+Options+Report | AS35: 44228 | AT35: Draft Bradford District Local Plan - both "Call for Sites" and "Preferred Options" (Regulation 18) | AU35: 44228 | AV35: 44235 | AW35: 44279 | AX35: https://www.bradford.gov.uk/planning-and-building-control/planning-policy/bradford-district-local-plan/ | BG35: 46204 | BH35: 46204 | BJ35: 46327 | BK35: 46327 | BM35: Summer 2028 | BN35: 46935 | BP35: LDS adopted Oct 2025 | BQ35: As of mid-2020, the Council is preparing a single Local Plan which includes work undertaken to date on the Core Strategy Partial Review and land allocations. | BS35: 45497 | BT35: 46024 | BU35: 45310 | BV35: 46024 | BW35: 46024 | BX35: Reg 18 completed | BZ35: Visual Ping
A36: E07000067 | C36: Braintree | D36: Braintree Local Plan (North Essex Garden Communities) Section 1 Review | E36: TBC | H36: Y | I36: N | J36: 44249 | W36: =IF(OR(X36="Yes", Y36="Web-page timetable", Z36="YES"), "Yes") -> Yes | X36: Yes | Y36: LDS Document | AA36: https://www.braintree.gov.uk/homepage/116/local-development-scheme-download | AB36: https://www.braintree.gov.uk/downloads/file/2023/local-development-scheme | AD36: 45962 | AE36: Jan/Feb 2025 | AF36: Issues and Options (Reg 18) | AG36: 46054 | AH36: 45677 | AI36: 45723 | AJ36: https://www.braintree.gov.uk/planning-building-control/braintree-district-development-plan/2 | AL36: 46054 | AM36: Preferred Options (Reg 18) | AN36: 46054 | BG36: 46235 | BH36: 46235 | BJ36: 46327 | BK36: 46327 | BM36: 46539 | BN36: 46539 | BP36: LDS Nov 2025 | BS36: 46031 | BT36: 46024 | BU36: 46031 | BV36: 46024 | BW36: 46024 | BX36: Reg 18 ongoing
A37: E07000143 | C37: Breckland | D37: Breckland Local Plan Full Update 2024-2041 | E37: 2317 | F37: 2024 | G37: 2041 | H37: N | I37: N | J37: 28 November 2019 (as amended by the partial update of 21 Sept 2023) | L37: YES | M37: Nutrient neutrality (March 2022) | W37: Yes | X37: Yes | Y37: LDS Document | AA37: https://www.breckland.gov.uk/local-plan-review | AB37: https://democracy.breckland.gov.uk/documents/g5348/Public%20reports%20pack%2003rd-Mar-2025%2011.00%20Cabinet.pdf?T=10 | AD37: 45717 | AE37: Jan - April 2023 | AF37: Issues and Options | AG37: 44927 | AH37: 44995 | AI37: 45065 | AJ37: https://www.breckland.gov.uk/article/19942/Local-Plan-Full-Update | AL37: Oct 2023 - Jan 2024 | AM37: emerging development strategy (Reg 18) | AN37: 45200 | AO37: 45299 | AP37: 45341 | AQ37: https://www.breckland.gov.uk/article/19942/Local-Plan-Full-Update | AS37: Spring 2024 | AT37: Draft Local Plan consultation | AU37: 45383 | AV37: 45446 | AW37: 45488 | AX37: https://www.breckland.gov.uk/article/19942/Local-Plan-Full-Update-2024 | AZ37: Oct - Dec 2025 | BA37: Revised Regulation 18 Consultation | BB37: 45931 | BC37: 45931 | BD37: 46006 | BE37: https://www.breckland.gov.uk/article/25391/Regulation-18-Local-Plan-Consultation-2025 | BG37: July - Sept 2026 | BH37: 46204 | BJ37: 46357 | BK37: 46357 | BM37: 2027 TBC | BN37: 2027 TBC | BP37: March 2025 LDS (as found in cabinet minutes of 3 March 2025) | BQ37: In September 2024, Breckland Council in Norfolk paused work on its local plan update despite the strategy going out of date in two months, citing a 47% rise in its annual housing requirement under proposed changes to the National Planning Policy Framework (NPPF). | BS37: 46034 | BT37: 45950 | BU37: 46034 | BV37: 45950 | BW37: 45950 | BX37: Reg 18 completed | BZ37: NEED A NEW VISUALPING ALERT once reg 18 starts
B38: E07000143-02 | C38: Breckland | D38: Breckland Local Plan - partial review non-strategic for our purposes | E38: 2184 | F38: 2011 | G38: 2036 | H38: N | I38: N | J38: 28 November 2019 (as amended by the partial update of 21 Sept 2023) | M38: Planning White Paper; Nutrient neutrality (March 2022) | O38: YES | P38: 44784 | Q38: 44894 | R38: 45167 | W38: =IF(OR(X38="Yes", Y38="Web-page timetable", Z38="YES"), "Yes") -> Yes | X38: Yes | Y38: LDS Document | AA38: https://www.breckland.gov.uk/local-plan-review | AB38: https://democracy.breckland.gov.uk/documents/g5348/Public%20reports%20pack%2003rd-Mar-2025%2011.00%20Cabinet.pdf?T=10 | AD38: 45717 | AE38: Q1 2022 - Q2 2022 | AF38: Issues and Options | AG38: 44593 | AH38: 44784 | AI38: 44827 | BG38: 44774 | BH38: 44774 | BI38: 11/08/2022 30/09/2022 | BJ38: 44866 | BK38: 44866 | BL38: 44866 | BM38: 45047 | BN38: 45047 | BO38: 45170 | BQ38: The Partial Review updates Policy INF03 of the Breckland Local Plan by removing the requirement for a more detailed review of four policies. They relate to housing provision, accommodation for gypsies and travellers, technical housing standards and the economic strategy. The Partial Review submitted for examination seeks to update Policy INF 03 by deleting this requirement, in favour of the production of a full Local Plan due to be submitted by the end of 2024. | BS38: 44628 | BT38: 45950 | BU38: 44463 | BV38: 44846 | BW38: 44846 | BX38: Adopted [partial update] | BZ38: Submitted Nov 2022
A39: E09000005 | C39: Brent | D39: Brent Local Plan | E39: TBA | H39: N | I39: N | J39: 44616 | K39: 40371 | W39: =IF(OR(X39="Yes", Y39="Web-page timetable", Z39="YES"), "Yes") -> Yes | X39: Yes | Y39: LDS Document | AA39: https://www.brent.gov.uk/localplan | AB39: https://www.brent.gov.uk/-/media/files/resident-documents/planning-and-bc-documents/local-development-scheme.pdf?rev=87535829340143c9af2ccdadddce3d1c&hash=0AE68BB76ED56E989EDA46E99B6A031A | AD39: 45748 | AE39: 46388 | AF39: First formal consultation | AG39: 46388 | BG39: 46753 | BH39: 46753 | BJ39: 46905 | BK39: 46905 | BM39: 47119 | BN39: 47119 | BP39: April 2025 LDS | BS39: 45142 | BT39: 45888 | BV39: 45888 | BW39: 45888 | BX39: new plan to be prepared under new system | BZ39: Adopted 24 Feb 2022
A40: E07000068 | C40: Brentwood | D40: Brentwood Local Plan | E40: TBA | H40: N | I40: N | J40: 44643 | K40: none [Mar 2022 adopted plan is first post-2004 Act Plan] | O40: YES | W40: =IF(OR(X40="Yes", Y40="Web-page timetable", Z40="YES"), "Yes") -> Yes | X40: Yes | Y40: LDS Document | AA40: https://www.brentwood.gov.uk/local-development-scheme-lds | AB40: https://www.brentwood.gov.uk/media/942 | AD40: 45689 | AE40: Q2 2026 | AF40: Preferred Options (equivalent) | AG40: 46143 | BG40: Q2 2027 | BH40: 46508 | BJ40: Q1 2028 | BK40: 46784 | BM40: Q1 2029 | BN40: 47150 | BP40: Feb 2025 LDS | BS40: 45961 | BT40: 45902 | BV40: 45902 | BW40: 45902 | BX40: new plan to be prepared under new system | CD40: Yes
...

Sheet This is the original VLS!

Sheet updated 12 Jan 2026

Sheet Pre-Reg 19 Emerging Plans
A1: LIVE DOCUMENT - DO NOT EDIT - SUMMARY OF LOCAL PLAN POSITION
A2: NOTE: PRE-PUBLICATION PLANS ONLY ARE RECORDED HERE
A3: ONSCODE | B3: Unique VLS code [only to be used where there is more than one plan] | C3: Local authority name | D3: "defunct LPA"? | E3: New LPA? (2019 - 2023) | F3: Title of Emerging Development Plan Document | G3: Emerging Plan Period Start (YYYY) | H3: Emerging Plan Period End (YYYY) | I3: Aligned Plan (Y/N) | J3: Joint Plan (Y/N) | K3: Last Plan Adopted | L3: First Reg 18 consultation (expected) | M3: First Reg 18 consultation (actual) | N3: Second Reg 18 consultation (expected) | O3: Second Reg 18 consultation (actual) | P3: Third Reg 18 consultation (expected) | Q3: Third Reg 18 consultation (actual) | R3: Fourth Reg 18 consultation (expected) | S3: Fourth Reg 18 consultation (actual) | T3: Expected Publication | U3: Expected Submission | V3: Expected Adoption | W3: Summary Stage | X3: Summary Stage for PowerBi Live or Completed Reg 18? | Y3: Date LDS checked (no change) | Z3: Date LDS updated | AA3: Date timetable checked (no change) | AB3: Date timetable updated
A4: E07000223 | C4: Adur | F4: =IF(VLOOKUP($A4,'8 Oct - LIVE LDS Data'!$A$3:$AAD$1504,4,FALSE)=0/1/1900,"",VLOOKUP($A4,'8 Oct - LIVE LDS Data'!$A$3:$AAD$1504,4,FALSE)) -> Adur Local Plan | G4: =IF(VLOOKUP($A4,'8 Oct - LIVE LDS Data'!$A$3:$AAD$1504,6,FALSE)=0/1/1900,"",VLOOKUP($A4,'8 Oct - LIVE LDS Data'!$A$3:$AAD$1504,6,FALSE)) -> 2024 | H4: =IF(VLOOKUP($A4,'8 Oct - LIVE LDS Data'!$A$3:$AAD$1504,7,FALSE)=0/1/1900,"",VLOOKUP($A4,'8 Oct - LIVE LDS Data'!$A$3:$AAD$1504,7,FALSE)) -> 2039 | I4: =IF(VLOOKUP($A4,'8 Oct - LIVE LDS Data'!$A$3:$AAD$1504,8,FALSE)=0/1/1900,"",VLOOKUP($A4,'8 Oct - LIVE LDS Data'!$A$3:$AAD$1504,8,FALSE)) -> N | J4: =IF(VLOOKUP($A4,'8 Oct - LIVE LDS Data'!$A$3:$AAD$1504,9,FALSE)=0/1/1900,"",VLOOKUP($A4,'8 Oct - LIVE LDS Data'!$A$3:$AAD$1504,9,FALSE)) -> N | K4: =IF(VLOOKUP($A4,'8 Oct - LIVE LDS Data'!$A$3:$AAD$1504,10,FALSE)=0/1/1900,"",VLOOKUP($A4,'8 Oct - LIVE LDS Data'!$A$3:$AAD$1504,10,FALSE)) -> 43083 | L4: =IF(VLOOKUP($A4,'8 Oct - LIVE LDS Data'!$A$3:$AAD$1504,34,FALSE)=0/1/1900,"",VLOOKUP($A4,'8 Oct - LIVE LDS Data'!$A$3:$AAD$1504,34,FALSE)) -> 45622 | M4: =IF(VLOOKUP($A4,'8 Oct - LIVE LDS Data'!$A$3:$AAD$1504,35,FALSE)=0/1/1900,"",VLOOKUP($A4,'8 Oct - LIVE LDS Data'!$A$3:$AAD$1504,35,FALSE)) -> 46027 | N4: =IF(VLOOKUP($A4,'8 Oct - LIVE LDS Data'!$A$3:$AAD$1504,41,FALSE)=0/1/1900,"",VLOOKUP($A4,'8 Oct - LIVE LDS Data'!$A$3:$AAD$1504,41,FALSE)) | O4: =IF(VLOOKUP($A4,'8 Oct - LIVE LDS Data'!$A$3:$AAD$1504,42,FALSE)=0/1/1900,"",VLOOKUP($A4,'8 Oct - LIVE LDS Data'!$A$3:$AAD$1504,42,FALSE)) | P4: =IF(VLOOKUP($A4,'8 Oct - LIVE LDS Data'!$A$3:$AAD$1504,48,FALSE)=0/1/1900,"",VLOOKUP($A4,'8 Oct - LIVE LDS Data'!$A$3:$AAD$1504,48,FALSE)) | Q4: =IF(VLOOKUP($A4,'8 Oct - LIVE LDS Data'!$A$3:$AAD$1504,49,FALSE)=0/1/1900,"",VLOOKUP($A4,'8 Oct - LIVE LDS Data'!$A$3:$AAD$1504,49,FALSE)) | R4: =IF(VLOOKUP($A4,'8 Oct - LIVE LDS Data'!$A$3:$AAD$1504,55,FALSE)=0/1/1900,"",VLOOKUP($A4,'8 Oct - LIVE LDS Data'!$A$3:$AAD$1504,55,FALSE)) | S4: =IF(VLOOKUP($A4,'8 Oct - LIVE LDS Data'!$A$3:$AAD$1504,56,FALSE)=0/1/1900,"",VLOOKUP($A4,'8 Oct - LIVE LDS Data'!$A$3:$AAD$1504,56,FALSE)) | T4: =IF(VLOOKUP($A4,'8 Oct - LIVE LDS Data'!$A$3:$AAD$1504,61,FALSE)=0/1/1900,"",VLOOKUP($A4,'8 Oct - LIVE LDS Data'!$A$3:$AAD$1504,61,FALSE)) | U4: =IF(VLOOKUP($A4,'8 Oct - LIVE LDS Data'!$A$3:$AAD$1504,64,FALSE)=0/1/1900,"",VLOOKUP($A4,'8 Oct - LIVE LDS Data'!$A$3:$AAD$1504,64,FALSE)) | V4: =IF(VLOOKUP($A4,'8 Oct - LIVE LDS Data'!$A$3:$AAD$1504,67,FALSE)=0/1/1900,"",VLOOKUP($A4,'8 Oct - LIVE LDS Data'!$A$3:$AAD$1504,67,FALSE)) | W4: =IF(VLOOKUP($A4,'8 Oct - LIVE LDS Data'!$A$3:$AAD$1504,80,FALSE)=0/1/1900,"",VLOOKUP($A4,'8 Oct - LIVE LDS Data'!$A$3:$AAD$1504,80,FALSE)) | X4: YES | Y4: =IF(VLOOKUP($A4,'8 Oct - LIVE LDS Data'!$A$3:$AAD$1504,73,FALSE)=0/1/1900,"",VLOOKUP($A4,'8 Oct - LIVE LDS Data'!$A$3:$AAD$1504,73,FALSE)) -> 45743 | Z4: =IF(VLOOKUP($A4,'8 Oct - LIVE LDS Data'!$A$3:$AAD$1504,74,FALSE)=0/1/1900,"",VLOOKUP($A4,'8 Oct - LIVE LDS Data'!$A$3:$AAD$1504,74,FALSE)) -> Shannon Franklin | AA4: =IF(VLOOKUP($A4,'8 Oct - LIVE LDS Data'!$A$3:$AAD$1504,76,FALSE)=0/1/1900,"",VLOOKUP($A4,'8 Oct - LIVE LDS Data'!$A$3:$AAD$1504,76,FALSE)) -> 45743 | AB4: =IF(VLOOKUP($A4,'8 Oct - LIVE LDS Data'!$A$3:$AAD$1504,77,FALSE)=0/1/1900,"",VLOOKUP($A4,'8 Oct - LIVE LDS Data'!$A$3:$AAD$1504,77,FALSE)) -> Shannon Franklin
A5: E07000224 | C5: Arun | F5: =IF(VLOOKUP($A5,'8 Oct - LIVE LDS Data'!$A$3:$AAD$1504,4,FALSE)=0/1/1900,"",VLOOKUP($A5,'8 Oct - LIVE LDS Data'!$A$3:$AAD$1504,4,FALSE)) -> Arun Local Plan Update 2023 - 2041 | G5: =IF(VLOOKUP($A5,'8 Oct - LIVE LDS Data'!$A$3:$AAD$1504,6,FALSE)=0/1/1900,"",VLOOKUP($A5,'8 Oct - LIVE LDS Data'!$A$3:$AAD$1504,6,FALSE)) -> 2023 | H5: =IF(VLOOKUP($A5,'8 Oct - LIVE LDS Data'!$A$3:$AAD$1504,7,FALSE)=0/1/1900,"",VLOOKUP($A5,'8 Oct - LIVE LDS Data'!$A$3:$AAD$1504,7,FALSE)) -> 2041 | I5: =IF(VLOOKUP($A5,'8 Oct - LIVE LDS Data'!$A$3:$AAD$1504,8,FALSE)=0/1/1900,"",VLOOKUP($A5,'8 Oct - LIVE LDS Data'!$A$3:$AAD$1504,8,FALSE)) -> N | J5: =IF(VLOOKUP($A5,'8 Oct - LIVE LDS Data'!$A$3:$AAD$1504,9,FALSE)=0/1/1900,"",VLOOKUP($A5,'8 Oct - LIVE LDS Data'!$A$3:$AAD$1504,9,FALSE)) -> N | K5: =IF(VLOOKUP($A5,'8 Oct - LIVE LDS Data'!$A$3:$AAD$1504,10,FALSE)=0/1/1900,"",VLOOKUP($A5,'8 Oct - LIVE LDS Data'!$A$3:$AAD$1504,10,FALSE)) -> 43299 | L5: =IF(VLOOKUP($A5,'8 Oct - LIVE LDS Data'!$A$3:$AAD$1504,34,FALSE)=0/1/1900,"",VLOOKUP($A5,'8 Oct - LIVE LDS Data'!$A$3:$AAD$1504,34,FALSE)) -> 45376 | M5: =IF(VLOOKUP($A5,'8 Oct - LIVE LDS Data'!$A$3:$AAD$1504,35,FALSE)=0/1/1900,"",VLOOKUP($A5,'8 Oct - LIVE LDS Data'!$A$3:$AAD$1504,35,FALSE)) -> 45536 | N5: =IF(VLOOKUP($A5,'8 Oct - LIVE LDS Data'!$A$3:$AAD$1504,41,FALSE)=0/1/1900,"",VLOOKUP($A5,'8 Oct - LIVE LDS Data'!$A$3:$AAD$1504,41,FALSE)) | O5: =IF(VLOOKUP($A5,'8 Oct - LIVE LDS Data'!$A$3:$AAD$1504,42,FALSE)=0/1/1900,"",VLOOKUP($A5,'8 Oct - LIVE LDS Data'!$A$3:$AAD$1504,42,FALSE)) | P5: =IF(VLOOKUP($A5,'8 Oct - LIVE LDS Data'!$A$3:$AAD$1504,48,FALSE)=0/1/1900,"",VLOOKUP($A5,'8 Oct - LIVE LDS Data'!$A$3:$AAD$1504,48,FALSE)) | Q5: =IF(VLOOKUP($A5,'8 Oct - LIVE LDS Data'!$A$3:$AAD$1504,49,FALSE)=0/1/1900,"",VLOOKUP($A5,'8 Oct - LIVE LDS Data'!$A$3:$AAD$1504,49,FALSE)) | R5: =IF(VLOOKUP($A5,'8 Oct - LIVE LDS Data'!$A$3:$AAD$1504,55,FALSE)=0/1/1900,"",VLOOKUP($A5,'8 Oct - LIVE LDS Data'!$A$3:$AAD$1504,55,FALSE)) | S5: =IF(VLOOKUP($A5,'8 Oct - LIVE LDS Data'!$A$3:$AAD$1504,56,FALSE)=0/1/1900,"",VLOOKUP($A5,'8 Oct - LIVE LDS Data'!$A$3:$AAD$1504,56,FALSE)) | T5: =IF(VLOOKUP($A5,'8 Oct - LIVE LDS Data'!$A$3:$AAD$1504,61,FALSE)=0/1/1900,"",VLOOKUP($A5,'8 Oct - LIVE LDS Data'!$A$3:$AAD$1504,61,FALSE)) | U5: =IF(VLOOKUP($A5,'8 Oct - LIVE LDS Data'!$A$3:$AAD$1504,64,FALSE)=0/1/1900,"",VLOOKUP($A5,'8 Oct - LIVE LDS Data'!$A$3:$AAD$1504,64,FALSE)) | V5: =IF(VLOOKUP($A5,'8 Oct - LIVE LDS Data'!$A$3:$AAD$1504,67,FALSE)=0/1/1900,"",VLOOKUP($A5,'8 Oct - LIVE LDS Data'!$A$3:$AAD$1504,67,FALSE)) | W5: =IF(VLOOKUP($A5,'8 Oct - LIVE LDS Data'!$A$3:$AAD$1504,80,FALSE)=0/1/1900,"",VLOOKUP($A5,'8 Oct - LIVE LDS Data'!$A$3:$AAD$1504,80,FALSE)) | X5: YES | Y5: =IF(VLOOKUP($A5,'8 Oct - LIVE LDS Data'!$A$3:$AAD$1504,73,FALSE)=0/1/1900,"",VLOOKUP($A5,'8 Oct - LIVE LDS Data'!$A$3:$AAD$1504,73,FALSE)) -> 45743 | Z5: =IF(VLOOKUP($A5,'8 Oct - LIVE LDS Data'!$A$3:$AAD$1504,74,FALSE)=0/1/1900,"",VLOOKUP($A5,'8 Oct - LIVE LDS Data'!$A$3:$AAD$1504,74,FALSE)) -> Shannon Franklin | AA5: =IF(VLOOKUP($A5,'8 Oct - LIVE LDS Data'!$A$3:$AAD$1504,76,FALSE)=0/1/1900,"",VLOOKUP($A5,'8 Oct - LIVE LDS Data'!$A$3:$AAD$1504,76,FALSE)) -> 45743 | AB5: =IF(VLOOKUP($A5,'8 Oct - LIVE LDS Data'!$A$3:$AAD$1504,77,FALSE)=0/1/1900,"",VLOOKUP($A5,'8 Oct - LIVE LDS Data'!$A$3:$AAD$1504,77,FALSE)) -> Shannon Franklin
A6: E07000105 | C6: Ashford | F6: =IF(VLOOKUP($A6,'8 Oct - LIVE LDS Data'!$A$3:$AAD$1504,4,FALSE)=0/1/1900,"",VLOOKUP($A6,'8 Oct - LIVE LDS Data'!$A$3:$AAD$1504,4,FALSE)) -> Ashford Local Plan 2042 | G6: =IF(VLOOKUP($A6,'8 Oct - LIVE LDS Data'!$A$3:$AAD$1504,6,FALSE)=0/1/1900,"",VLOOKUP($A6,'8 Oct - LIVE LDS Data'!$A$3:$AAD$1504,6,FALSE)) | H6: =IF(VLOOKUP($A6,'8 Oct - LIVE LDS Data'!$A$3:$AAD$1504,7,FALSE)=0/1/1900,"",VLOOKUP($A6,'8 Oct - LIVE LDS Data'!$A$3:$AAD$1504,7,FALSE)) -> 2042 | I6: =IF(VLOOKUP($A6,'8 Oct - LIVE LDS Data'!$A$3:$AAD$1504,8,FALSE)=0/1/1900,"",VLOOKUP($A6,'8 Oct - LIVE LDS Data'!$A$3:$AAD$1504,8,FALSE)) -> N | J6: =IF(VLOOKUP($A6,'8 Oct - LIVE LDS Data'!$A$3:$AAD$1504,9,FALSE)=0/1/1900,"",VLOOKUP($A6,'8 Oct - LIVE LDS Data'!$A$3:$AAD$1504,9,FALSE)) -> N | K6: =IF(VLOOKUP($A6,'8 Oct - LIVE LDS Data'!$A$3:$AAD$1504,10,FALSE)=0/1/1900,"",VLOOKUP($A6,'8 Oct - LIVE LDS Data'!$A$3:$AAD$1504,10,FALSE)) -> 43517 | L6: =IF(VLOOKUP($A6,'8 Oct - LIVE LDS Data'!$A$3:$AAD$1504,34,FALSE)=0/1/1900,"",VLOOKUP($A6,'8 Oct - LIVE LDS Data'!$A$3:$AAD$1504,34,FALSE)) -> 45887 | M6: =IF(VLOOKUP($A6,'8 Oct - LIVE LDS Data'!$A$3:$AAD$1504,35,FALSE)=0/1/1900,"",VLOOKUP($A6,'8 Oct - LIVE LDS Data'!$A$3:$AAD$1504,35,FALSE)) -> 45943 | N6: =IF(VLOOKUP($A6,'8 Oct - LIVE LDS Data'!$A$3:$AAD$1504,41,FALSE)=0/1/1900,"",VLOOKUP($A6,'8 Oct - LIVE LDS Data'!$A$3:$AAD$1504,41,FALSE)) | O6: =IF(VLOOKUP($A6,'8 Oct - LIVE LDS Data'!$A$3:$AAD$1504,42,FALSE)=0/1/1900,"",VLOOKUP($A6,'8 Oct - LIVE LDS Data'!$A$3:$AAD$1504,42,FALSE)) | P6: =IF(VLOOKUP($A6,'8 Oct - LIVE LDS Data'!$A$3:$AAD$1504,48,FALSE)=0/1/1900,"",VLOOKUP($A6,'8 Oct - LIVE LDS Data'!$A$3:$AAD$1504,48,FALSE)) | Q6: =IF(VLOOKUP($A6,'8 Oct - LIVE LDS Data'!$A$3:$AAD$1504,49,FALSE)=0/1/1900,"",VLOOKUP($A6,'8 Oct - LIVE LDS Data'!$A$3:$AAD$1504,49,FALSE)) | R6: =IF(VLOOKUP($A6,'8 Oct - LIVE LDS Data'!$A$3:$AAD$1504,55,FALSE)=0/1/1900,"",VLOOKUP($A6,'8 Oct - LIVE LDS Data'!$A$3:$AAD$1504,55,FALSE)) | S6: =IF(VLOOKUP($A6,'8 Oct - LIVE LDS Data'!$A$3:$AAD$1504,56,FALSE)=0/1/1900,"",VLOOKUP($A6,'8 Oct - LIVE LDS Data'!$A$3:$AAD$1504,56,FALSE)) | T6: =IF(VLOOKUP($A6,'8 Oct - LIVE LDS Data'!$A$3:$AAD$1504,61,FALSE)=0/1/1900,"",VLOOKUP($A6,'8 Oct - LIVE LDS Data'!$A$3:$AAD$1504,61,FALSE)) | U6: =IF(VLOOKUP($A6,'8 Oct - LIVE LDS Data'!$A$3:$AAD$1504,64,FALSE)=0/1/1900,"",VLOOKUP($A6,'8 Oct - LIVE LDS Data'!$A$3:$AAD$1504,64,FALSE)) | V6: =IF(VLOOKUP($A6,'8 Oct - LIVE LDS Data'!$A$3:$AAD$1504,67,FALSE)=0/1/1900,"",VLOOKUP($A6,'8 Oct - LIVE LDS Data'!$A$3:$AAD$1504,67,FALSE)) | W6: =IF(VLOOKUP($A6,'8 Oct - LIVE LDS Data'!$A$3:$AAD$1504,80,FALSE)=0/1/1900,"",VLOOKUP($A6,'8 Oct - LIVE LDS Data'!$A$3:$AAD$1504,80,FALSE)) | X6: YES | Y6: =IF(VLOOKUP($A6,'8 Oct - LIVE LDS Data'!$A$3:$AAD$1504,73,FALSE)=0/1/1900,"",VLOOKUP($A6,'8 Oct - LIVE LDS Data'!$A$3:$AAD$1504,73,FALSE)) -> 45743 | Z6: =IF(VLOOKUP($A6,'8 Oct - LIVE LDS Data'!$A$3:$AAD$1504,74,FALSE)=0/1/1900,"",VLOOKUP($A6,'8 Oct - LIVE LDS Data'!$A$3:$AAD$1504,74,FALSE)) -> Shannon Franklin | AA6: =IF(VLOOKUP($A6,'8 Oct - LIVE LDS Data'!$A$3:$AAD$1504,76,FALSE)=0/1/1900,"",VLOOKUP($A6,'8 Oct - LIVE LDS Data'!$A$3:$AAD$1504,76,FALSE)) -> 45918 | AB6: =IF(VLOOKUP($A6,'8 Oct - LIVE LDS Data'!$A$3:$AAD$1504,77,FALSE)=0/1/1900,"",VLOOKUP($A6,'8 Oct - LIVE LDS Data'!$A$3:$AAD$1504,77,FALSE)) -> Robert Putnam
